Workbook

Sheet 그린폰단가
A1: 제조사 | B1: 단말정보 | D1: 매입가
B2: 모델명 | C2: 펫네임 | D2: A+ | E2: A | F2: B
A3: 애플 | B3: AIP6 16 | C3: 아이폰 6 | D3: 20000 | E3: 20000 | F3: 2000
B4: AIP6 64 | C4: 아이폰 6 | D4: 30000 | E4: 30000 | F4: 3000
B5: AIP6 128 | C5: 아이폰 6 | D5: 30000 | E5: 30000 | F5: 3000
B6: AIP6P 16 | C6: 아이폰 6+ | D6: 35000 | E6: 35000 | F6: 4000
B7: AIP6P 64 | C7: 아이폰 6+ | D7: 50000 | E7: 50000 | F7: 5000
B8: AIP6P 128 | C8: 아이폰 6+ | D8: 50000 | E8: 50000 | F8: 5000
B9: AIP6S 16 | C9: 아이폰 6S | D9: 30000 | E9: 30000 | F9: 3000
B10: AIP6S 64 | C10: 아이폰 6S | D10: 45000 | E10: 45000 | F10: 5000
B11: AIP6S 128 | C11: 아이폰 6S | D11: 45000 | E11: 45000 | F11: 5000
B12: AIP6SP 16 | C12: 아이폰 6S+ | D12: 80000 | E12: 80000 | F12: 8000
B13: AIP6SP 64 | C13: 아이폰 6S+ | D13: 100000 | E13: 100000 | F13: 10000
B14: AIP6SP 128 | C14: 아이폰 6S+ | D14: 100000 | E14: 100000 | F14: 10000
B15: AIP7 32 | C15: 아이폰 7 | D15: 70000 | E15: 70000 | F15: 7000
... B35: AIPXSM 512 | C35: 아이폰 XS MAX | D35: 560000 | E35: 560000 | F35: 56000
A36: 삼성 | B36: SM-G920K/S/L | C36: 갤럭시 S6 | D36: 15000 | E36: 15000 | F36: 2000
B37: SM-G925K/S/L | C37: 갤럭시 S6 엣지 | D37: 20000 | E37: 20000 | F37: 2000
B38: SM-G928K/S/L | C38: 갤럭시 S6 엣지 Plus | D38: 50000 | E38: 50000 | F38: 5000
B39: SM-G930K/S/L | C39: 갤럭시 S7 | D39: 40000 | E39: 40000 | F39: 4000
B40: SM-G935K/S/L | C40: 갤럭시 S7 엣지 | D40: 65000 | E40: 65000 | F40: 7000
B41: SM-950N(K/S/L) | C41: 갤럭시 S8 | D41: 125000 | E41: 125000 | F41: 13000
B42: SM-G955N(K/S/L) | C42: 갤럭시 S8 플러스 | D42: 155000 | E42: 155000 | F42: 16000
B43: SM-G960 | C43: 갤럭시 S9 | D43: 180000 | E43: 180000 | F43: 18000
B44: SM-G965 | C44: 갤럭시 S9 플러스 | D44: 215000 | E44: 215000 | F44: 22000
B45: SM-A510K/S/L | C45: 갤럭시 A 5 2016 | D45: 10000 | E45: 10000 | F45: 1000
B46: SM-A520K/S/L | C46: 갤럭시 A 5 2017 | D46: 20000 | E46: 20000 | F46: 2000
B47: SM-A710K/S/L | C47: 갤럭시 A 7 2016 | D47: 15000 | E47: 15000 | F47: 2000
B48: SM-A750N | C48: 갤럭시 A 7 2018 | D48: 65000 | E48: 65000 | F48: 7000
... B60: SM-J730K | C60: Galaxy J7 2017 | D60: 30000 | E60: 30000 | F60: 3000
A61: 엘지 | B61: LGM-G600K | C61: G6 | D61: 5000 | E61: 5000 | F61: 1000
B62: LGM-G710K | C62: G7 | D62: 45000 | E62: 45000 | F62: 5000
B63: LG-F600K | C63: V10 | D63: 5000 | E63: 5000 | F63: 1000
B64: LG-F800K | C64: V20 | D64: 5000 | E64: 5000 | F64: 1000
B65: LG-V300K | C65: V30 | D65: 20000 | E65: 20000 | F65: 2000
B66: LG-X600 | C66: Q6 | D66: 5000 | E66: 5000 | F66: 1000

Sheet 안내

Sheet 주요정책 및 유의사항
B2: 유형 | C2: 요금제 | D2: 모델 | E2: 혜택 | F2: 비고
B3: 전유형 | C3: 베이직 | D3: 갤럭시 폴더블4 | E3: 최대 62만원 | F3: 플립4/폴더4
B4: 전유형 | C4: 베이직 | D4: 갤럴시 S22(화이트) | E4: 최대 62만원 | F4: 10대 한정
B5: 전유형 | C5: 슬림이상 | D5: 갤럭시 A33 | E5: 최소 50만원 | F5: 슬림이상 단말 "0원"
B6: 전유형 | C6: 세이브이상 | D6: 갤럭시 점프2 | E6: 최소 40만원 | F6: 전요금 단말 "0원"
B7: 전유형 | C7: 슬림플러스이상 | D7: 아이폰SE3_128G | E7: 최소 50만원 | F7: 슬림P이상 단말 "0원"
B9: ■ 유의사항
B10: 대상 | C10: 요금할인 | D10: 내용
B11: 요금제하향 | C11: 122일 이후 | D11: 차액정산금 미발생되는 최저 요금제 확인 필수
B12: 단기해지 | C12: 180일 | D12: 기간 內 지급액 전액 환수, 이후 사내특판 혜택 적용 불가
B13: 5G 기존 가입자 | C13: 180일 | D13: 기간 內 사내판매 혜택적용 불가
B14: 고객 VOC | D14: 권유자 전달 및 소명 진행
B16: ■ 지급
B17: 대상 | C17: 지급방법 | D17: 지급시기 | E17: 내용
B18: 고객 | C18: 개통단말 | D18: 개통즉시 | E18: 출고가에서 바로 할인
B19: 권유자 | C19: 복리포인트/현금 | D19: 익월23일 | E19: 0~15만/건

Sheet Sheet1
B3: 모델 | C3: 요금제 | D3: MNP | E3: 비고
B4: 갤럭시 S23 | C4: 베이직 | D4: 640000 | E4: 요금할인만 운영 권유자 혜택 (Max 15만원)_정책 內
C5: 심플 | D5: 540000
C6: 슬림플러스 | D6: 540000
C7: 슬림 | D7: 540000
C8: 세이브 | D8: 440000
B9: 아이폰 SE3 | C9: 베이직 | D9: 550000
C10: 심플 | D10: 490000
C11: 슬림플러스 | D11: 490000
C12: 슬림 | D12: 450000
C13: 세이브 | D13: 390000
B14: 아이폰 14 | C14: 베이직 | D14: 450000
C15: 심플 | D15: 410000
C16: 슬림플러스 | D16: 410000
C17: 슬림 | D17: 370000
C18: 세이브 | D18: 290000
B19: * 기타모델은 재고 문의 후 접수 필요
B22: 모델 | D22: 5G | E22: 비고
B23: A7(Lite), A9+, S9 | D23: 150000 | E23: - 모단말 요금제 121일이상 유지조건 단, 010신규 한정 181일 이상 유지조건 - 동일명의 당월 개통건 한정 - 폰(신규/기변 가능), 2nd(신규만가능)
B24: 갤럭시 북3 Go 5G | D24: 150000
B25: 워치 5~8 | D25: 200000
B26: 워치 울트라 | D26: 240000
B27: 애플 워치 SE2, 7 | D27: 150000
B28: * 동일 제조사에 한해 정책 지원
B29: * 대상 모델: 갤럭시 워치(S25군, 폴더블6/7, S24군, S23군, S22군, 폴더블5, 폴더블4, 폴드3 한정)
B30: 애플워치(아이폰 14/15 포함한 아이폰류)

Sheet 사내 MGM_1Q 1호(0101 ~)
D1: 사이트: | F1: https://shopmns.com/ktmnsmgm
E2: 공통지원금(확인사이트): | H2: 공통지원금 | 휴대폰지원금 | KT
E4: 공통지원금, 요금할인 개통가능
D7: 제조사 | E7: 구분 | F7: 모델명 | G7: 모델펫네임 | H7: 출고가 | I7: 요금제 | J7: 요금제 구간 | K7: 합계 | N7: 권유자선택 | P7: 고객 즉시할인 | R7: 고객선택 | S7: 요금할인
A8: 모델 | B8: 출고가 | C8: 모델명&요금제 | K8: 010신규 | L8: 번호이동 | M8: 기기변경 | N8: 0원 | O8: 010신규 | P8: 번호이동 | Q8: 기기변경 | R8: 기기변경 | S8: 최종할부금 | T8: 월요금(예상)
D9: 유심 | E9: 5G | F9: 유심단독 | I9: 베이직 | J9: 80K이상 | K9: 170000 | L9: 300000
G10: NZA0003759 | I10: 심플30G | J10: 61K~80K미만 | K10: 150000 | L10: 220000
G11: 기업무선_유심_중고(그룹사) | I11: 슬림10G | J11: 49K~61K미만 | K11: 120000 | L11: 180000
I12: 슬림4G | J12: 33K~49K미만 | K12: 80000 | L12: 130000
A13: SM-F766NK | B13: =VLOOKUP($A13,출고가!$C:$E,3,FALSE) -> 1485000 | C13: =A13&I13 -> SM-F766NK베이직 | D13: 삼성 | E13: 5G | F13: =A13 -> SM-F766NK | G13: =VLOOKUP(F13,[1]출고가!C:D,2,0) -> 갤럭시 Z Flip7 | H13: =B13 -> 1485000 | I13: 베이직 | J13: 80K이상 | K13: 580000 | L13: 580000 | M13: 580000 | N13: =IF($N$8="0원",0,IF($N$8="5만",50000,IF($N$8="10만",100000,150000))) -> 0 | O13: =IF(K13-$N13>0,K13-$N13,0) -> 580000 | P13: =IF(L13-$N13>0,L13-$N13,0) -> 580000 | Q13: =IF(M13-$N13>0,M13-$N13,0) -> 580000 | R13: =IF($R$8=$O$8,O13,IF($R$8=$P$8,P13,Q13)) -> 580000 | S13: =IF(B13-R13>0,B13-R13,0) -> 905000 | T13: =ROUNDDOWN((S13/24*1.059)+(VLOOKUP(I13,구분자!$P:$Q,2,FALSE)*0.75),-3) -> 99000
A14: SM-F766NK | B14: =VLOOKUP($A14,출고가!$C:$E,3,FALSE) -> 1485000 | C14: =A14&I14 -> SM-F766NK심플30G | I14: 심플30G | J14: 61K~80K미만 | K14: 530000 | L14: 530000 | M14: 530000 | N14: =IF($N$8="0원",0,IF($N$8="5만",50000,IF($N$8="10만",100000,150000))) -> 0 | O14: =IF(K14-$N14>0,K14-$N14,0) -> 530000 | P14: =IF(L14-$N14>0,L14-$N14,0) -> 530000 | Q14: =IF(M14-$N14>0,M14-$N14,0) -> 530000 | R14: =IF($R$8=$O$8,O14,IF($R$8=$P$8,P14,Q14)) -> 530000 | S14: =IF(B14-R14>0,B14-R14,0) -> 955000 | T14: =ROUNDDOWN((S14/24*1.059)+(VLOOKUP(I14,구분자!$P:$Q,2,FALSE)*0.75),-3) -> 87000
A15: SM-F766NK | B15: =VLOOKUP($A15,출고가!$C:$E,3,FALSE) -> 1485000 | C15: =A15&I15 -> SM-F766NK슬림10G | I15: 슬림10G | J15: 49K~61K미만 | K15: 480000 | L15: 480000 | M15: 480000 | N15: =IF($N$8="0원",0,IF($N$8="5만",50000,IF($N$8="10만",100000,150000))) -> 0 | O15: =IF(K15-$N15>0,K15-$N15,0) -> 480000 | P15: =IF(L15-$N15>0,L15-$N15,0) -> 480000 | Q15: =IF(M15-$N15>0,M15-$N15,0) -> 480000 | R15: =IF($R$8=$O$8,O15,IF($R$8=$P$8,P15,Q15)) -> 480000 | S15: =IF(B15-R15>0,B15-R15,0) -> 1005000 | T15: =ROUNDDOWN((S15/24*1.059)+(VLOOKUP(I15,구분자!$P:$Q,2,FALSE)*0.75),-3) -> 81000
A16: SM-F766NK | B16: =VLOOKUP($A16,출고가!$C:$E,3,FALSE) -> 1485000 | C16: =A16&I16 -> SM-F766NK슬림4G | I16: 슬림4G | J16: 33K~49K미만 | K16: 350000 | L16: 350000 | M16: 350000 | N16: =IF($N$8="0원",0,IF($N$8="5만",50000,IF($N$8="10만",100000,150000))) -> 0 | O16: =IF(K16-$N16>0,K16-$N16,0) -> 350000 | P16: =IF(L16-$N16>0,L16-$N16,0) -> 350000 | Q16: =IF(M16-$N16>0,M16-$N16,0) -> 350000 | R16: =IF($R$8=$O$8,O16,IF($R$8=$P$8,P16,Q16)) -> 350000 | S16: =IF(B16-R16>0,B16-R16,0) -> 1135000 | T16: =ROUNDDOWN((S16/24*1.059)+(VLOOKUP(I16,구분자!$P:$Q,2,FALSE)*0.75),-3) -> 77000
A17: SM-F766NK512 | B17: =VLOOKUP($A17,출고가!$C:$E,3,FALSE) -> 1643400 | C17: =A17&I17 -> SM-F766NK512베이직 | E17: 5G | F17: =A17 -> SM-F766NK512 | G17: =VLOOKUP(F17,[1]출고가!C:D,2,0) -> 갤럭시 Z Flip7 512GB | H17: =B17 -> 1643400 | I17: 베이직 | J17: 80K이상 | K17: 580000 | L17: 580000 | M17: 580000 | N17: =IF($N$8="0원",0,IF($N$8="5만",50000,IF($N$8="10만",100000,150000))) -> 0 | O17: =IF(K17-$N17>0,K17-$N17,0) -> 580000 | P17: =IF(L17-$N17>0,L17-$N17,0) -> 580000 | Q17: =IF(M17-$N17>0,M17-$N17,0) -> 580000 | R17: =IF($R$8=$O$8,O17,IF($R$8=$P$8,P17,Q17)) -> 580000 | S17: =IF(B17-R17>0,B17-R17,0) -> 1063400 | T17: =ROUNDDOWN((S17/24*1.059)+(VLOOKUP(I17,구분자!$P:$Q,2,FALSE)*0.75),-3) -> 106000
A18: SM-F766NK512 | B18: =VLOOKUP($A18,출고가!$C:$E,3,FALSE) -> 1643400 | C18: =A18&I18 -> SM-F766NK512심플30G | I18: 심플30G | J18: 61K~80K미만 | K18: 530000 | L18: 530000 | M18: 530000 | N18: =IF($N$8="0원",0,IF($N$8="5만",50000,IF($N$8="10만",100000,150000))) -> 0 | O18: =IF(K18-$N18>0,K18-$N18,0) -> 530000 | P18: =IF(L18-$N18>0,L18-$N18,0) -> 530000 | Q18: =IF(M18-$N18>0,M18-$N18,0) -> 530000 | R18: =IF($R$8=$O$8,O18,IF($R$8=$P$8,P18,Q18)) -> 530000 | S18: =IF(B18-R18>0,B18-R18,0) -> 1113400 | T18: =ROUNDDOWN((S18/24*1.059)+(VLOOKUP(I18,구분자!$P:$Q,2,FALSE)*0.75),-3) -> 94000
A19: SM-F766NK512 | B19: =VLOOKUP($A19,출고가!$C:$E,3,FALSE) -> 1643400 | C19: =A19&I19 -> SM-F766NK512슬림10G | G19: 재고 문의필요 | I19: 슬림10G | J19: 49K~61K미만 | K19: 480000 | L19: 480000 | M19: 480000 | N19: =IF($N$8="0원",0,IF($N$8="5만",50000,IF($N$8="10만",100000,150000))) -> 0 | O19: =IF(K19-$N19>0,K19-$N19,0) -> 480000 | P19: =IF(L19-$N19>0,L19-$N19,0) -> 480000 | Q19: =IF(M19-$N19>0,M19-$N19,0) -> 480000 | R19: =IF($R$8=$O$8,O19,IF($R$8=$P$8,P19,Q19)) -> 480000 | S19: =IF(B19-R19>0,B19-R19,0) -> 1163400 | T19: =ROUNDDOWN((S19/24*1.059)+(VLOOKUP(I19,구분자!$P:$Q,2,FALSE)*0.75),-3) -> 88000
A20: SM-F766NK512 | B20: =VLOOKUP($A20,출고가!$C:$E,3,FALSE) -> 1643400 | C20: =A20&I20 -> SM-F766NK512슬림4G | I20: 슬림4G | J20: 33K~49K미만 | K20: 350000 | L20: 350000 | M20: 350000 | N20: =IF($N$8="0원",0,IF($N$8="5만",50000,IF($N$8="10만",100000,150000))) -> 0 | O20: =IF(K20-$N20>0,K20-$N20,0) -> 350000 | P20: =IF(L20-$N20>0,L20-$N20,0) -> 350000 | Q20: =IF(M20-$N20>0,M20-$N20,0) -> 350000 | R20: =IF($R$8=$O$8,O20,IF($R$8=$P$8,P20,Q20)) -> 350000 | S20: =IF(B20-R20>0,B20-R20,0) -> 1293400 | T20: =ROUNDDOWN((S20/24*1.059)+(VLOOKUP(I20,구분자!$P:$Q,2,FALSE)*0.75),-3) -> 84000
A21: SM-F966NK | B21: =VLOOKUP($A21,출고가!$C:$E,3,FALSE) -> 2379300 | C21: =A21&I21 -> SM-F966NK베이직 | E21: 5G | F21: =A21 -> SM-F966NK | G21: =VLOOKUP(F21,[1]출고가!C:D,2,0) -> 갤럭시 Z Fold7 | H21: =B21 -> 2379300 | I21: 베이직 | J21: 80K이상 | K21: 580000 | L21: 580000 | M21: 580000 | N21: =IF($N$8="0원",0,IF($N$8="5만",50000,IF($N$8="10만",100000,150000))) -> 0 | O21: =IF(K21-$N21>0,K21-$N21,0) -> 580000 | P21: =IF(L21-$N21>0,L21-$N21,0) -> 580000 | Q21: =IF(M21-$N21>0,M21-$N21,0) -> 580000 | R21: =IF($R$8=$O$8,O21,IF($R$8=$P$8,P21,Q21)) -> 580000 | S21: =IF(B21-R21>0,B21-R21,0) -> 1799300 | T21: =ROUNDDOWN((S21/24*1.059)+(VLOOKUP(I21,구분자!$P:$Q,2,FALSE)*0.75),-3) -> 139000
A22: SM-F966NK | B22: =VLOOKUP($A22,출고가!$C:$E,3,FALSE) -> 2379300 | C22: =A22&I22 -> SM-F966NK심플30G | I22: 심플30G | J22: 61K~80K미만 | K22: 530000 | L22: 530000 | M22: 530000 | N22: =IF($N$8="0원",0,IF($N$8="5만",50000,IF($N$8="10만",100000,150000))) -> 0 | O22: =IF(K22-$N22>0,K22-$N22,0) -> 530000 | P22: =IF(L22-$N22>0,L22-$N22,0) -> 530000 | Q22: =IF(M22-$N22>0,M22-$N22,0) -> 530000 | R22: =IF($R$8=$O$8,O22,IF($R$8=$P$8,P22,Q22)) -> 530000 | S22: =IF(B22-R22>0,B22-R22,0) -> 1849300 | T22: =ROUNDDOWN((S22/24*1.059)+(VLOOKUP(I22,구분자!$P:$Q,2,FALSE)*0.75),-3) -> 127000
A23: SM-F966NK | B23: =VLOOKUP($A23,출고가!$C:$E,3,FALSE) -> 2379300 | C23: =A23&I23 -> SM-F966NK슬림10G | I23: 슬림10G | J23: 49K~61K미만 | K23: 480000 | L23: 480000 | M23: 480000 | N23: =IF($N$8="0원",0,IF($N$8="5만",50000,IF($N$8="10만",100000,150000))) -> 0 | O23: =IF(K23-$N23>0,K23-$N23,0) -> 480000 | P23: =IF(L23-$N23>0,L23-$N23,0) -> 480000 | Q23: =IF(M23-$N23>0,M23-$N23,0) -> 480000 | R23: =IF($R$8=$O$8,O23,IF($R$8=$P$8,P23,Q23)) -> 480000 | S23: =IF(B23-R23>0,B23-R23,0) -> 1899300 | T23: =ROUNDDOWN((S23/24*1.059)+(VLOOKUP(I23,구분자!$P:$Q,2,FALSE)*0.75),-3) -> 121000
A24: SM-F966NK | B24: =VLOOKUP($A24,출고가!$C:$E,3,FALSE) -> 2379300 | C24: =A24&I24 -> SM-F966NK슬림4G | I24: 슬림4G | J24: 33K~49K미만 | K24: 350000 | L24: 350000 | M24: 350000 | N24: =IF($N$8="0원",0,IF($N$8="5만",50000,IF($N$8="10만",100000,150000))) -> 0 | O24: =IF(K24-$N24>0,K24-$N24,0) -> 350000 | P24: =IF(L24-$N24>0,L24-$N24,0) -> 350000 | Q24: =IF(M24-$N24>0,M24-$N24,0) -> 350000 | R24: =IF($R$8=$O$8,O24,IF($R$8=$P$8,P24,Q24)) -> 350000 | S24: =IF(B24-R24>0,B24-R24,0) -> 2029300 | T24: =ROUNDDOWN((S24/24*1.059)+(VLOOKUP(I24,구분자!$P:$Q,2,FALSE)*0.75),-3) -> 117000
A25: SM-F966NK512 | B25: =VLOOKUP($A25,출고가!$C:$E,3,FALSE) -> 2537700 | C25: =A25&I25 -> SM-F966NK512베이직 | E25: 5G | F25: =A25 -> SM-F966NK512 | G25: =VLOOKUP(F25,[1]출고가!C:D,2,0) -> 갤럭시 Z Fold7 512GB | H25: =B25 -> 2537700 | I25: 베이직 | J25: 80K이상 | K25: 580000 | L25: 580000 | M25: 580000 | N25: =IF($N$8="0원",0,IF($N$8="5만",50000,IF($N$8="10만",100000,150000))) -> 0 | O25: =IF(K25-$N25>0,K25-$N25,0) -> 580000 | P25: =IF(L25-$N25>0,L25-$N25,0) -> 580000 | Q25: =IF(M25-$N25>0,M25-$N25,0) -> 580000 | R25: =IF($R$8=$O$8,O25,IF($R$8=$P$8,P25,Q25)) -> 580000 | S25: =IF(B25-R25>0,B25-R25,0) -> 1957700 | T25: =ROUNDDOWN((S25/24*1.059)+(VLOOKUP(I25,구분자!$P:$Q,2,FALSE)*0.75),-3) -> 146000
A26: SM-F966NK512 | B26: =VLOOKUP($A26,출고가!$C:$E,3,FALSE) -> 2537700 | C26: =A26&I26 -> SM-F966NK512심플30G | I26: 심플30G | J26: 61K~80K미만 | K26: 530000 | L26: 530000 | M26: 530000 | N26: =IF($N$8="0원",0,IF($N$8="5만",50000,IF($N$8="10만",100000,150000))) -> 0 | O26: =IF(K26-$N26>0,K26-$N26,0) -> 530000 | P26: =IF(L26-$N26>0,L26-$N26,0) -> 530000 | Q26: =IF(M26-$N26>0,M26-$N26,0) -> 530000 | R26: =IF($R$8=$O$8,O26,IF($R$8=$P$8,P26,Q26)) -> 530000 | S26: =IF(B26-R26>0,B26-R26,0) -> 2007700 | T26: =ROUNDDOWN((S26/24*1.059)+(VLOOKUP(I26,구분자!$P:$Q,2,FALSE)*0.75),-3) -> 134000
A27: SM-F966NK512 | B27: =VLOOKUP($A27,출고가!$C:$E,3,FALSE) -> 2537700 | C27: =A27&I27 -> SM-F966NK512슬림10G | G27: 재고 문의필요 | I27: 슬림10G | J27: 49K~61K미만 | K27: 480000 | L27: 480000 | M27: 480000 | N27: =IF($N$8="0원",0,IF($N$8="5만",50000,IF($N$8="10만",100000,150000))) -> 0 | O27: =IF(K27-$N27>0,K27-$N27,0) -> 480000 | P27: =IF(L27-$N27>0,L27-$N27,0) -> 480000 | Q27: =IF(M27-$N27>0,M27-$N27,0) -> 480000 | R27: =IF($R$8=$O$8,O27,IF($R$8=$P$8,P27,Q27)) -> 480000 | S27: =IF(B27-R27>0,B27-R27,0) -> 2057700 | T27: =ROUNDDOWN((S27/24*1.059)+(VLOOKUP(I27,구분자!$P:$Q,2,FALSE)*0.75),-3) -> 128000
A28: SM-F966NK512 | B28: =VLOOKUP($A28,출고가!$C:$E,3,FALSE) -> 2537700 | C28: =A28&I28 -> SM-F966NK512슬림4G | I28: 슬림4G | J28: 33K~49K미만 | K28: 350000 | L28: 350000 | M28: 350000 | N28: =IF($N$8="0원",0,IF($N$8="5만",50000,IF($N$8="10만",100000,150000))) -> 0 | O28: =IF(K28-$N28>0,K28-$N28,0) -> 350000 | P28: =IF(L28-$N28>0,L28-$N28,0) -> 350000 | Q28: =IF(M28-$N28>0,M28-$N28,0) -> 350000 | R28: =IF($R$8=$O$8,O28,IF($R$8=$P$8,P28,Q28)) -> 350000 | S28: =IF(B28-R28>0,B28-R28,0) -> 2187700 | T28: =ROUNDDOWN((S28/24*1.059)+(VLOOKUP(I28,구분자!$P:$Q,2,FALSE)*0.75),-3) -> 124000
A29: SM-S937NK | B29: =VLOOKUP($A29,출고가!$C:$E,3,FALSE) -> 1496000 | C29: =A29&I29 -> SM-S937NK베이직 | E29: 5G | F29: =A29 -> SM-S937NK | G29: =VLOOKUP(F29,출고가!C:D,2,0) -> 갤럭시S25 엣지 (256GB) | H29: =B29 -> 1496000 | I29: 베이직 | J29: 80K이상 | K29: 580000 | L29: 580000 | M29: 580000 | N29: =IF($N$8="0원",0,IF($N$8="5만",50000,IF($N$8="10만",100000,150000))) -> 0 | O29: =IF(K29-$N29>0,K29-$N29,0) -> 580000 | P29: =IF(L29-$N29>0,L29-$N29,0) -> 580000 | Q29: =IF(M29-$N29>0,M29-$N29,0) -> 580000 | R29: =IF($R$8=$O$8,O29,IF($R$8=$P$8,P29,Q29)) -> 580000 | S29: =IF(B29-R29>0,B29-R29,0) -> 916000 | T29: =ROUNDDOWN((S29/24*1.059)+(VLOOKUP(I29,구분자!$P:$Q,2,FALSE)*0.75),-3) -> 100000
A30: SM-S937NK | B30: =VLOOKUP($A30,출고가!$C:$E,3,FALSE) -> 1496000 | C30: =A30&I30 -> SM-S937NK심플30G | I30: 심플30G | J30: 61K~80K미만 | K30: 530000 | L30: 530000 | M30: 530000 | N30: =IF($N$8="0원",0,IF($N$8="5만",50000,IF($N$8="10만",100000,150000))) -> 0 | O30: =IF(K30-$N30>0,K30-$N30,0) -> 530000 | P30: =IF(L30-$N30>0,L30-$N30,0) -> 530000 | Q30: =IF(M30-$N30>0,M30-$N30,0) -> 530000 | R30: =IF($R$8=$O$8,O30,IF($R$8=$P$8,P30,Q30)) -> 530000 | S30: =IF(B30-R30>0,B30-R30,0) -> 966000 | T30: =ROUNDDOWN((S30/24*1.059)+(VLOOKUP(I30,구분자!$P:$Q,2,FALSE)*0.75),-3) -> 88000
A31: SM-S937NK | B31: =VLOOKUP($A31,출고가!$C:$E,3,FALSE) -> 1496000 | C31: =A31&I31 -> SM-S937NK슬림10G | I31: 슬림10G | J31: 49K~61K미만 | K31: 480000 | L31: 480000 | M31: 480000 | N31: =IF($N$8="0원",0,IF($N$8="5만",50000,IF($N$8="10만",100000,150000))) -> 0 | O31: =IF(K31-$N31>0,K31-$N31,0) -> 480000 | P31: =IF(L31-$N31>0,L31-$N31,0) -> 480000 | Q31: =IF(M31-$N31>0,M31-$N31,0) -> 480000 | R31: =IF($R$8=$O$8,O31,IF($R$8=$P$8,P31,Q31)) -> 480000 | S31: =IF(B31-R31>0,B31-R31,0) -> 1016000 | T31: =ROUNDDOWN((S31/24*1.059)+(VLOOKUP(I31,구분자!$P:$Q,2,FALSE)*0.75),-3) -> 82000
A32: SM-S937NK | B32: =VLOOKUP($A32,출고가!$C:$E,3,FALSE) -> 1496000 | C32: =A32&I32 -> SM-S937NK슬림4G | I32: 슬림4G | J32: 33K~49K미만 | K32: 350000 | L32: 350000 | M32: 350000 | N32: =IF($N$8="0원",0,IF($N$8="5만",50000,IF($N$8="10만",100000,150000))) -> 0 | O32: =IF(K32-$N32>0,K32-$N32,0) -> 350000 | P32: =IF(L32-$N32>0,L32-$N32,0) -> 350000 | Q32: =IF(M32-$N32>0,M32-$N32,0) -> 350000 | R32: =IF($R$8=$O$8,O32,IF($R$8=$P$8,P32,Q32)) -> 350000 | S32: =IF(B32-R32>0,B32-R32,0) -> 1146000 | T32: =ROUNDDOWN((S32/24*1.059)+(VLOOKUP(I32,구분자!$P:$Q,2,FALSE)*0.75),-3) -> 78000
A33: SM-S931NK | B33: =VLOOKUP($A33,출고가!$C:$E,3,FALSE) -> 1155000 | C33: =A33&I33 -> SM-S931NK베이직 | E33: 5G | F33: =A33 -> SM-S931NK | G33: =VLOOKUP(F33,출고가!C:D,2,0) -> 갤럭시S25 (256GB) | H33: =B33 -> 1155000 | I33: 베이직 | J33: 80K이상 | K33: 580000 | L33: 580000 | M33: 580000 | N33: =IF($N$8="0원",0,IF($N$8="5만",50000,IF($N$8="10만",100000,150000))) -> 0 | O33: =IF(K33-$N33>0,K33-$N33,0) -> 580000 | P33: =IF(L33-$N33>0,L33-$N33,0) -> 580000 | Q33: =IF(M33-$N33>0,M33-$N33,0) -> 580000 | R33: =IF($R$8=$O$8,O33,IF($R$8=$P$8,P33,Q33)) -> 580000 | S33: =IF(B33-R33>0,B33-R33,0) -> 575000 | T33: =ROUNDDOWN((S33/24*1.059)+(VLOOKUP(I33,구분자!$P:$Q,2,FALSE)*0.75),-3) -> 85000
A34: SM-S931NK | B34: =VLOOKUP($A34,출고가!$C:$E,3,FALSE) -> 1155000 | C34: =A34&I34 -> SM-S931NK심플30G | I34: 심플30G | J34: 61K~80K미만 | K34: 530000 | L34: 530000 | M34: 530000 | N34: =IF($N$8="0원",0,IF($N$8="5만",50000,IF($N$8="10만",100000,150000))) -> 0 | O34: =IF(K34-$N34>0,K34-$N34,0) -> 530000 | P34: =IF(L34-$N34>0,L34-$N34,0) -> 530000 | Q34: =IF(M34-$N34>0,M34-$N34,0) -> 530000 | R34: =IF($R$8=$O$8,O34,IF($R$8=$P$8,P34,Q34)) -> 530000 | S34: =IF(B34-R34>0,B34-R34,0) -> 625000 | T34: =ROUNDDOWN((S34/24*1.059)+(VLOOKUP(I34,구분자!$P:$Q,2,FALSE)*0.75),-3) -> 73000
A35: SM-S931NK | B35: =VLOOKUP($A35,출고가!$C:$E,3,FALSE) -> 1155000 | C35: =A35&I35 -> SM-S931NK슬림10G | I35: 슬림10G | J35: 49K~61K미만 | K35: 480000 | L35: 480000 | M35: 480000 | N35: =IF($N$8="0원",0,IF($N$8="5만",50000,IF($N$8="10만",100000,150000))) -> 0 | O35: =IF(K35-$N35>0,K35-$N35,0) -> 480000 | P35: =IF(L35-$N35>0,L35-$N35,0) -> 480000 | Q35: =IF(M35-$N35>0,M35-$N35,0) -> 480000 | R35: =IF($R$8=$O$8,O35,IF($R$8=$P$8,P35,Q35)) -> 480000 | S35: =IF(B35-R35>0,B35-R35,0) -> 675000 | T35: =ROUNDDOWN((S35/24*1.059)+(VLOOKUP(I35,구분자!$P:$Q,2,FALSE)*0.75),-3) -> 67000
A36: SM-S931NK | B36: =VLOOKUP($A36,출고가!$C:$E,3,FALSE) -> 1155000 | C36: =A36&I36 -> SM-S931NK슬림4G | I36: 슬림4G | J36: 33K~49K미만 | K36: 350000 | L36: 350000 | M36: 350000 | N36: =IF($N$8="0원",0,IF($N$8="5만",50000,IF($N$8="10만",100000,150000))) -> 0 | O36: =IF(K36-$N36>0,K36-$N36,0) -> 350000 | P36: =IF(L36-$N36>0,L36-$N36,0) -> 350000 | Q36: =IF(M36-$N36>0,M36-$N36,0) -> 350000 | R36: =IF($R$8=$O$8,O36,IF($R$8=$P$8,P36,Q36)) -> 350000 | S36: =IF(B36-R36>0,B36-R36,0) -> 805000 | T36: =ROUNDDOWN((S36/24*1.059)+(VLOOKUP(I36,구분자!$P:$Q,2,FALSE)*0.75),-3) -> 63000
A37: SM-S936NK | B37: =VLOOKUP($A37,출고가!$C:$E,3,FALSE) -> 1353000 | C37: =A37&I37 -> SM-S936NK베이직 | E37: 5G | F37: =A37 -> SM-S936NK | G37: =VLOOKUP(F37,출고가!C:D,2,0) -> 갤럭시S25+ (256GB) | H37: =B37 -> 1353000 | I37: 베이직 | J37: 80K이상 | K37: 580000 | L37: 580000 | M37: 580000 | N37: =IF($N$8="0원",0,IF($N$8="5만",50000,IF($N$8="10만",100000,150000))) -> 0 | O37: =IF(K37-$N37>0,K37-$N37,0) -> 580000 | P37: =IF(L37-$N37>0,L37-$N37,0) -> 580000 | Q37: =IF(M37-$N37>0,M37-$N37,0) -> 580000 | R37: =IF($R$8=$O$8,O37,IF($R$8=$P$8,P37,Q37)) -> 580000 | S37: =IF(B37-R37>0,B37-R37,0) -> 773000 | T37: =ROUNDDOWN((S37/24*1.059)+(VLOOKUP(I37,구분자!$P:$Q,2,FALSE)*0.75),-3) -> 94000
A38: SM-S936NK | B38: =VLOOKUP($A38,출고가!$C:$E,3,FALSE) -> 1353000 | C38: =A38&I38 -> SM-S936NK심플30G | I38: 심플30G | J38: 61K~80K미만 | K38: 530000 | L38: 530000 | M38: 530000 | N38: =IF($N$8="0원",0,IF($N$8="5만",50000,IF($N$8="10만",100000,150000))) -> 0 | O38: =IF(K38-$N38>0,K38-$N38,0) -> 530000 | P38: =IF(L38-$N38>0,L38-$N38,0) -> 530000 | Q38: =IF(M38-$N38>0,M38-$N38,0) -> 530000 | R38: =IF($R$8=$O$8,O38,IF($R$8=$P$8,P38,Q38)) -> 530000 | S38: =IF(B38-R38>0,B38-R38,0) -> 823000 | T38: =ROUNDDOWN((S38/24*1.059)+(VLOOKUP(I38,구분자!$P:$Q,2,FALSE)*0.75),-3) -> 82000
A39: SM-S936NK | B39: =VLOOKUP($A39,출고가!$C:$E,3,FALSE) -> 1353000 | C39: =A39&I39 -> SM-S936NK슬림10G | I39: 슬림10G | J39: 49K~61K미만 | K39: 480000 | L39: 480000 | M39: 480000 | N39: =IF($N$8="0원",0,IF($N$8="5만",50000,IF($N$8="10만",100000,150000))) -> 0 | O39: =IF(K39-$N39>0,K39-$N39,0) -> 480000 | P39: =IF(L39-$N39>0,L39-$N39,0) -> 480000 | Q39: =IF(M39-$N39>0,M39-$N39,0) -> 480000 | R39: =IF($R$8=$O$8,O39,IF($R$8=$P$8,P39,Q39)) -> 480000 | S39: =IF(B39-R39>0,B39-R39,0) -> 873000 | T39: =ROUNDDOWN((S39/24*1.059)+(VLOOKUP(I39,구분자!$P:$Q,2,FALSE)*0.75),-3) -> 76000
A40: SM-S936NK | B40: =VLOOKUP($A40,출고가!$C:$E,3,FALSE) -> 1353000 | C40: =A40&I40 -> SM-S936NK슬림4G | I40: 슬림4G | J40: 33K~49K미만 | K40: 350000 | L40: 350000 | M40: 350000 | N40: =IF($N$8="0원",0,IF($N$8="5만",50000,IF($N$8="10만",100000,150000))) -> 0 | O40: =IF(K40-$N40>0,K40-$N40,0) -> 350000 | P40: =IF(L40-$N40>0,L40-$N40,0) -> 350000 | Q40: =IF(M40-$N40>0,M40-$N40,0) -> 350000 | R40: =IF($R$8=$O$8,O40,IF($R$8=$P$8,P40,Q40)) -> 350000 | S40: =IF(B40-R40>0,B40-R40,0) -> 1003000 | T40: =ROUNDDOWN((S40/24*1.059)+(VLOOKUP(I40,구분자!$P:$Q,2,FALSE)*0.75),-3) -> 72000
A41: SM-S938NK | B41: =VLOOKUP($A41,출고가!$C:$E,3,FALSE) -> 1698400 | C41: =A41&I41 -> SM-S938NK베이직 | E41: 5G | F41: =A41 -> SM-S938NK | G41: =VLOOKUP(F41,출고가!C:D,2,0) -> 갤럭시S25 울트라 (256GB) | H41: =B41 -> 1698400 | I41: 베이직 | J41: 80K이상 | K41: 580000 | L41: 580000 | M41: 580000 | N41: =IF($N$8="0원",0,IF($N$8="5만",50000,IF($N$8="10만",100000,150000))) -> 0 | O41: =IF(K41-$N41>0,K41-$N41,0) -> 580000 | P41: =IF(L41-$N41>0,L41-$N41,0) -> 580000 | Q41: =IF(M41-$N41>0,M41-$N41,0) -> 580000 | R41: =IF($R$8=$O$8,O41,IF($R$8=$P$8,P41,Q41)) -> 580000 | S41: =IF(B41-R41>0,B41-R41,0) -> 1118400 | T41: =ROUNDDOWN((S41/24*1.059)+(VLOOKUP(I41,구분자!$P:$Q,2,FALSE)*0.75),-3) -> 109000
A42: SM-S938NK | B42: =VLOOKUP($A42,출고가!$C:$E,3,FALSE) -> 1698400 | C42: =A42&I42 -> SM-S938NK심플30G | I42: 심플30G | J42: 61K~80K미만 | K42: 530000 | L42: 530000 | M42: 530000 | N42: =IF($N$8="0원",0,IF($N$8="5만",50000,IF($N$8="10만",100000,150000))) -> 0 | O42: =IF(K42-$N42>0,K42-$N42,0) -> 530000 | P42: =IF(L42-$N42>0,L42-$N42,0) -> 530000 | Q42: =IF(M42-$N42>0,M42-$N42,0) -> 530000 | R42: =IF($R$8=$O$8,O42,IF($R$8=$P$8,P42,Q42)) -> 530000 | S42: =IF(B42-R42>0,B42-R42,0) -> 1168400 | T42: =ROUNDDOWN((S42/24*1.059)+(VLOOKUP(I42,구분자!$P:$Q,2,FALSE)*0.75),-3) -> 97000
A43: SM-S938NK | B43: =VLOOKUP($A43,출고가!$C:$E,3,FALSE) -> 1698400 | C43: =A43&I43 -> SM-S938NK슬림10G | I43: 슬림10G | J43: 49K~61K미만 | K43: 480000 | L43: 480000 | M43: 480000 | N43: =IF($N$8="0원",0,IF($N$8="5만",50000,IF($N$8="10만",100000,150000))) -> 0 | O43: =IF(K43-$N43>0,K43-$N43,0) -> 480000 | P43: =IF(L43-$N43>0,L43-$N43,0) -> 480000 | Q43: =IF(M43-$N43>0,M43-$N43,0) -> 480000 | R43: =IF($R$8=$O$8,O43,IF($R$8=$P$8,P43,Q43)) -> 480000 | S43: =IF(B43-R43>0,B43-R43,0) -> 1218400 | T43: =ROUNDDOWN((S43/24*1.059)+(VLOOKUP(I43,구분자!$P:$Q,2,FALSE)*0.75),-3) -> 91000
...

Sheet Sheet3
C5: 갤럭시S24 울트라 256G | I5: 아이폰16E 128G
F6: 공시개통 | G6: 요할개통 | L6: 공시개통 | M6: 요할개통
C7: 단말기 | E7: 최초 구매가 | F7: 1544400 | G7: 1544400 | I7: 단말기 | K7: 최초 구매가 | L7: 1133000 | M7: 1133000
E8: 할인 | F8: =550000+100000 -> 650000 | G8: =550000+100000 -> 650000 | K8: 할인 | L8: 520000 | M8: 520000
E9: 공시할인 | F9: 600000 | K9: 공시할인 | L9: 600000
E10: 최종 구매가 | F10: =F7-F8-F9 -> 294400 | G10: =G7-G8-G9 -> 894400 | K10: 최종 구매가 | L10: =L7-L8-L9 -> 13000 | M10: =M7-M8-M9 -> 613000
C11: 요금 | E11: Y베이직 | F11: 80000 | G11: 80000 | I11: 요금 | K11: Y틴 | L11: 47000 | M11: 47000
C12: 월납부 | D12: 최초6개월 | E12: 단말 | F12: =F10/24+F10*5.9%/24 -> 12990.4 | G12: =G10/24+G10*5.9%/24 -> 39465.4 | I12: 월납부 | J12: 24개월 동일 | K12: 단말 | L12: =L10/24+L10*5.9%/24 -> 573.625 | M12: =M10/24+M10*5.9%/24 -> 27048.625
E13: 요금(Y베이직) | F13: 80000 | G13: =80000*0.75 -> 60000 | K13: 요금(Y틴) | L13: =L11 -> 47000 | M13: =M11*0.75 -> 35250
E14: 최종납부 | F14: =F12+F13 -> 92990.4 | G14: =G12+G13 -> 99465.4 | K14: 최종납부 | L14: =L12+L13 -> 47573.625 | M14: =M12+M13 -> 62298.625
D15: 이후 18개월 | E15: 단말 | F15: =F12 -> 12990.4 | G15: =G12 -> 39465.4 | J15: 이후 18개월 | K15: 단말 | L15: =L12 -> 573.625 | M15: =M12 -> 27048.625
E16: 요금(슬림14G) | F16: 55000 | G16: =55000*0.75 -> 41250 | K16: 요금(슬림14G) | L16: 55000 | M16: =55000*0.75 -> 41250
E17: 최종납부 | F17: =F15+F16 -> 67990.4 | G17: =G15+G16 -> 80715.4 | K17: 최종납부 | L17: =L15+L16 -> 55573.625 | M17: =M15+M16 -> 68298.625
C18: 총납부(24개월) | F18: =F14*6+F17*18 -> 1781769.6 | G18: =G14*6+G17*18 -> 2049669.6 | I18: 총납부(24개월) | L18: =L14*24 -> 1141767 | M18: =M14*24 -> 1495167

Sheet Sheet2
C2: 요금제
C4: 티빙/지니 초이스 프리미엄 | D4: 130000
C5: (유튜브 프리미엄) 초이스 프리미엄 | D5: 130000
C6: 넷플릭스 초이스 프리미엄 | D6: 130000
C7: 시즌/지니 초이스 프리미엄 | D7: 130000
C8: 티빙/밀리 초이스 프리미엄 | D8: 130000
C9: 디즈니+ 초이스 프리미엄 | D9: 130000
C10: BC바로 카드 초이스 프리미엄 | D10: 130000
C11: 현대카드 초이스 프리미엄 | D11: 130000
C12: 우리카드 초이스 프리미엄 | D12: 130000
C13: 코웨이 초이스 프리미엄 | D13: 130000
C14: 삼성 초이스 프리미엄 | D14: 130000
C15: 디바이스 초이스 프리미엄 | D15: 130000
... C54: 5G Y슬림 | D54: 55000
C55: 5G Y틴 | D55: 47000 | E55: 55000 | F55: 슬림
C57: 베이직 | D57: 80000
C58: 5G 심플 | D58: 69000
C59: 5G 심플 110GB | D59: 69000
C60: 5G 심플 70GB | D60: 65000
C61: 5G 심플 50GB | D61: 63000
C62: 5G 심플 30GB | D62: 61000
C63: 5G 슬림 플러스 | D63: 61000
C64: 5G 슬림 21GB | D64: 58000
C65: 5G 슬림(이월) 21GB | D65: 58000
C66: 5G 슬림 | D66: 55000
C67: 5G 슬림 14GB | D67: 55000
C68: 5G 슬림(이월) 14GB | D68: 55000
... C76: 5G 슬림(이월) 4GB | D76: 37000
C77: 5G 주니어 | D77: 38000 | E77: 55000 | F77: 슬림
C78: 5G 주니어 슬림 | D78: 28000 | E78: 45000 | F78: 세이브
C81: 5G 시니어 베이직 | D81: 49000 | E81: 61000 | F81: 슬림플러스
C82: 5G 시니어 A형 | D82: 44000 | E82: 55000 | F82: 슬림
C83: 5G 시니어 B형 | D83: 42000 | E83: 55000 | F83: 슬림
C84: 5G 시니어 C형 | D84: 41000 | E84: 55000 | F84: 슬림
C87: 베이직 복지 | D87: 80000
C88: 심플 복지 | D88: 69000
C89: 슬림 복지 | D89: 55000
C92: LTE 베이직 | D92: 33000
C93: 데이터투게더Watch | D93: 11000
C94: 5G 데이터투게더 | D94: 19800
...

Sheet 개별접수 URL
B3: 모델 | C3: 모델명 | D3: 형태 | E3: URL
D4: 신규
D5: 기변
D6: MNP
B7: SM-F956NK | C7: Z Fold6 | D7: 신규 | E7: https://online.kt.com/index.jsp?prdcID=DB092B16-13AE-4132-875E-367872F58991
D8: 기변 | E8: https://online.kt.com/index.jsp?prdcID=331AE147-ADA1-4381-902E-16231FB152C7
D9: MNP | E9: https://online.kt.com/index.jsp?prdcID=D14DE1CF-2CCE-4FE6-A3E3-0D283E30C400
B10: SM-F741NK512 | C10: Z Flip6 | D10: 신규 | E10: https://online.kt.com/index.jsp?prdcID=B38A5447-CDE3-458E-90E2-55FB94F25FF5
D11: 기변 | E11: https://online.kt.com/index.jsp?prdcID=9D5BFC31-DD17-4498-9D9D-967C321F918D
D12: MNP | E12: https://online.kt.com/index.jsp?prdcID=5407438A-D35D-4A6F-806F-0352342A460A
B13: SM-S921NK | C13: S24 | D13: 신규 | E13: http://online.kt.com/index.jsp?prdcID=3C018A8E-CD0A-46C2-82C6-8C19F261F4F6
D14: 기변 | E14: http://online.kt.com/index.jsp?prdcID=F55AC94D-D2BD-497E-9E91-C8DB5910F3FC
D15: MNP | E15: http://online.kt.com/index.jsp?prdcID=1B7F40BF-F23F-4A9C-A158-909373C3AA4B
B16: SM-S926NK | C16: S24+ | D16: 신규
D17: 기변
D18: MNP
B19: SM-S926NK | C19: S24+ | D19: 신규 | E19: http://online.kt.com/index.jsp?prdcID=4E89440A-9F1A-4186-A399-5C4E9B6A1D96
D20: 기변 | E20: http://online.kt.com/index.jsp?prdcID=F07584FF-1983-4E9E-BBA8-7D677278B3F7
D21: MNP | E21: http://online.kt.com/index.jsp?prdcID=3EBDA557-F83B-447D-9486-2F2F4D860F76
B22: SM-S928NK | C22: S24울트라 | D22: 신규
D23: 기변
D24: MNP
B25: SM-S928NK | C25: S24울트라 | D25: 신규 | E25: http://online.kt.com/index.jsp?prdcID=3447A192-DF9A-42A2-BA20-10AA29012229
D26: 기변 | E26: http://online.kt.com/index.jsp?prdcID=BF263F71-1E40-4072-9D86-A1DD7CC54CB5
D27: MNP | E27: http://online.kt.com/index.jsp?prdcID=2EE05656-2B01-4F0E-B525-27E5118A4C0C
B28: SM-F731 | C28: Z Flip5 | D28: 신규 | E28: http://online.kt.com/index.jsp?prdcID=BCC0215A-3499-49CC-8670-FD0C8E7DE2E4
D29: 기변 | E29: http://online.kt.com/index.jsp?prdcID=30E74E4D-8CEC-4D6A-A18C-A1A8D1F3B659
D30: MNP | E30: http://online.kt.com/index.jsp?prdcID=FA18D316-5CA1-4544-93A3-9CEBE5CD78BA
B31: SM-F946 | C31: Z Fold5 | D31: 신규 | E31: http://online.kt.com/index.jsp?prdcID=DA656364-AA28-4184-B227-F00E368B519E
D32: 기변 | E32: http://online.kt.com/index.jsp?prdcID=ED41E141-9E3A-429A-913E-0A49C7C55A89
D33: MNP | E33: http://online.kt.com/index.jsp?prdcID=B87DFC09-7680-4C2A-B750-2880DF211FE8
B34: SM-S711 | C34: S23FE | D34: 신규 | E34: http://online.kt.com/index.jsp?prdcID=7FEC2B12-17E2-4ED5-B70F-BEAB0B4BA465
D35: 기변 | E35: http://online.kt.com/index.jsp?prdcID=71FFEA20-0DD7-43C7-8FB7-298913879154
D36: MNP | E36: http://online.kt.com/index.jsp?prdcID=0E1D90A6-3387-4D4A-8A36-A5025D57EF00
B37: SM-S911 | C37: S23 | D37: 신규 | E37: http://online.kt.com/index.jsp?prdcID=1E3314B5-54BE-497C-A3D7-FD74902163C3
D38: 기변 | E38: http://online.kt.com/index.jsp?prdcID=31D76568-748B-4611-96B5-B6619AC2E343
D39: MNP | E39: http://online.kt.com/index.jsp?prdcID=9CEB6A5E-4088-4BC3-85A9-584CF7A6BEF9
B40: SM-S916 | C40: S23+ | D40: 신규 | E40: http://online.kt.com/index.jsp?prdcID=CCD369C4-5C73-4F57-90D5-5900E91B1835
D41: 기변 | E41: http://online.kt.com/index.jsp?prdcID=2491AC2F-FEF5-435C-A0C9-77E997D49979
D42: MNP | E42: http://online.kt.com/index.jsp?prdcID=E6598325-4444-47D3-9215-12ECDB7364EC
...

Sheet 사내 MGM_1Q 2호(0311 ~) (2)
D1: 제조사 | E1: 구분 | F1: 모델명 | G1: 모델펫네임 | H1: 출고가 | I1: 요금제 | J1: 요금제 구간 | K1: 합계
A2: 모델 | B2: 출고가 | C2: 모델명&요금제 | D2: 제조사 | E2: 구분 | F2: 모델명 | G2: 모델펫네임 | H2: 출고가 | I2: 요금제 | J2: 요금제 구간 | K2: 010신규 | L2: 번호이동 | M2: 기기변경
D3: 유심 | E3: 5G | F3: 유심단독 | I3: 베이직 | J3: 80K이상 | K3: 170000 | L3: 300000
D4: 유심 | E4: 5G | F4: 유심단독 | I4: 심플30G | J4: 61K~80K미만 | K4: 150000 | L4: 220000
D5: 유심 | E5: 5G | F5: 유심단독 | I5: 슬림10G | J5: 49K~61K미만 | K5: 120000 | L5: 180000
D6: 유심 | E6: 5G | F6: 유심단독 | I6: 슬림4G | J6: 33K~49K미만 | K6: 80000 | L6: 130000
A7: SM-S942NK | B7: =VLOOKUP($A7,출고가!$C:$E,3,FALSE) -> 1254000 | C7: =A7&I7 -> SM-S942NK베이직 | D7: 삼성 | E7: 5G | F7: =A7 -> SM-S942NK | G7: =VLOOKUP(F7,출고가!C:D,2,0) -> 갤럭시S26 (256GB) | H7: =B7 -> 1254000 | I7: 베이직 | J7: 80K이상 | K7: 450000 | L7: 450000 | M7: 400000
A8: SM-S942NK | B8: =VLOOKUP($A8,출고가!$C:$E,3,FALSE) -> 1254000 | C8: =A8&I8 -> SM-S942NK심플30G | D8: 삼성 | E8: 5G | F8: =A8 -> SM-S942NK | G8: =VLOOKUP(F8,출고가!C:D,2,0) -> 갤럭시S26 (256GB) | H8: =B8 -> 1254000 | I8: 심플30G | J8: 61K~80K미만 | K8: 350000 | L8: 350000 | M8: 300000
A9: SM-S942NK | B9: =VLOOKUP($A9,출고가!$C:$E,3,FALSE) -> 1254000 | C9: =A9&I9 -> SM-S942NK슬림10G | D9: 삼성 | E9: 5G | F9: =A9 -> SM-S942NK | G9: =VLOOKUP(F9,출고가!C:D,2,0) -> 갤럭시S26 (256GB) | H9: =B9 -> 1254000 | I9: 슬림10G | J9: 49K~61K미만 | K9: 250000 | L9: 250000 | M9: 200000
A10: SM-S942NK | B10: =VLOOKUP($A10,출고가!$C:$E,3,FALSE) -> 1254000 | C10: =A10&I10 -> SM-S942NK슬림4G | D10: 삼성 | E10: 5G | F10: =A10 -> SM-S942NK | G10: =VLOOKUP(F10,출고가!C:D,2,0) -> 갤럭시S26 (256GB) | H10: =B10 -> 1254000 | I10: 슬림4G | J10: 33K~49K미만 | K10: 150000 | L10: 150000 | M10: 100000
A11: SM-S947NK | B11: =VLOOKUP($A11,출고가!$C:$E,3,FALSE) -> 1452000 | C11: =A11&I11 -> SM-S947NK베이직 | D11: 삼성 | E11: 5G | F11: =A11 -> SM-S947NK | G11: =VLOOKUP(F11,출고가!C:D,2,0) -> 갤럭시S26+ (256GB) | H11: =B11 -> 1452000 | I11: 베이직 | J11: 80K이상 | K11: 450000 | L11: 450000 | M11: 400000
A12: SM-S947NK | B12: =VLOOKUP($A12,출고가!$C:$E,3,FALSE) -> 1452000 | C12: =A12&I12 -> SM-S947NK심플30G | D12: 삼성 | E12: 5G | F12: =A12 -> SM-S947NK | G12: =VLOOKUP(F12,출고가!C:D,2,0) -> 갤럭시S26+ (256GB) | H12: =B12 -> 1452000 | I12: 심플30G | J12: 61K~80K미만 | K12: 350000 | L12: 350000 | M12: 300000
A13: SM-S947NK | B13: =VLOOKUP($A13,출고가!$C:$E,3,FALSE) -> 1452000 | C13: =A13&I13 -> SM-S947NK슬림10G | D13: 삼성 | E13: 5G | F13: =A13 -> SM-S947NK | G13: =VLOOKUP(F13,출고가!C:D,2,0) -> 갤럭시S26+ (256GB) | H13: =B13 -> 1452000 | I13: 슬림10G | J13: 49K~61K미만 | K13: 250000 | L13: 250000 | M13: 200000
A14: SM-S947NK | B14: =VLOOKUP($A14,출고가!$C:$E,3,FALSE) -> 1452000 | C14: =A14&I14 -> SM-S947NK슬림4G | D14: 삼성 | E14: 5G | F14: =A14 -> SM-S947NK | G14: =VLOOKUP(F14,출고가!C:D,2,0) -> 갤럭시S26+ (256GB) | H14: =B14 -> 1452000 | I14: 슬림4G | J14: 33K~49K미만 | K14: 150000 | L14: 150000 | M14: 100000
A15: SM-S948NK | B15: =VLOOKUP($A15,출고가!$C:$E,3,FALSE) -> 1797400 | C15: =A15&I15 -> SM-S948NK베이직 | D15: 삼성 | E15: 5G | F15: =A15 -> SM-S948NK | G15: =VLOOKUP(F15,출고가!C:D,2,0) -> 갤럭시S26 울트라 (256GB) | H15: =B15 -> 1797400 | I15: 베이직 | J15: 80K이상 | K15: 450000 | L15: 450000 | M15: 400000
A16: SM-S948NK | B16: =VLOOKUP($A16,출고가!$C:$E,3,FALSE) -> 1797400 | C16: =A16&I16 -> SM-S948NK심플30G | D16: 삼성 | E16: 5G | F16: =A16 -> SM-S948NK | G16: =VLOOKUP(F16,출고가!C:D,2,0) -> 갤럭시S26 울트라 (256GB) | H16: =B16 -> 1797400 | I16: 심플30G | J16: 61K~80K미만 | K16: 350000 | L16: 350000 | M16: 300000
A17: SM-S948NK | B17: =VLOOKUP($A17,출고가!$C:$E,3,FALSE) -> 1797400 | C17: =A17&I17 -> SM-S948NK슬림10G | D17: 삼성 | E17: 5G | F17: =A17 -> SM-S948NK | G17: =VLOOKUP(F17,출고가!C:D,2,0) -> 갤럭시S26 울트라 (256GB) | H17: =B17 -> 1797400 | I17: 슬림10G | J17: 49K~61K미만 | K17: 250000 | L17: 250000 | M17: 200000
A18: SM-S948NK | B18: =VLOOKUP($A18,출고가!$C:$E,3,FALSE) -> 1797400 | C18: =A18&I18 -> SM-S948NK슬림4G | D18: 삼성 | E18: 5G | F18: =A18 -> SM-S948NK | G18: =VLOOKUP(F18,출고가!C:D,2,0) -> 갤럭시S26 울트라 (256GB) | H18: =B18 -> 1797400 | I18: 슬림4G | J18: 33K~49K미만 | K18: 150000 | L18: 150000 | M18: 100000
A19: SM-F766NK | B19: =VLOOKUP($A19,출고가!$C:$E,3,FALSE) -> 1485000 | C19: =A19&I19 -> SM-F766NK베이직 | D19: 삼성 | E19: 5G | F19: =A19 -> SM-F766NK | G19: =VLOOKUP(F19,[1]출고가!C:D,2,0) -> 갤럭시 Z Flip7 | H19: =B19 -> 1485000 | I19: 베이직 | J19: 80K이상 | K19: 580000 | L19: 580000 | M19: 580000
A20: SM-F766NK | B20: =VLOOKUP($A20,출고가!$C:$E,3,FALSE) -> 1485000 | C20: =A20&I20 -> SM-F766NK심플30G | D20: 삼성 | E20: 5G | F20: =A20 -> SM-F766NK | G20: =VLOOKUP(F20,[1]출고가!C:D,2,0) -> 갤럭시 Z Flip7 | H20: =B20 -> 1485000 | I20: 심플30G | J20: 61K~80K미만 | K20: 530000 | L20: 530000 | M20: 530000
A21: SM-F766NK | B21: =VLOOKUP($A21,출고가!$C:$E,3,FALSE) -> 1485000 | C21: =A21&I21 -> SM-F766NK슬림10G | D21: 삼성 | E21: 5G | F21: =A21 -> SM-F766NK | G21: =VLOOKUP(F21,[1]출고가!C:D,2,0) -> 갤럭시 Z Flip7 | H21: =B21 -> 1485000 | I21: 슬림10G | J21: 49K~61K미만 | K21: 480000 | L21: 480000 | M21: 480000
A22: SM-F766NK | B22: =VLOOKUP($A22,출고가!$C:$E,3,FALSE) -> 1485000 | C22: =A22&I22 -> SM-F766NK슬림4G | D22: 삼성 | E22: 5G | F22: =A22 -> SM-F766NK | G22: =VLOOKUP(F22,[1]출고가!C:D,2,0) -> 갤럭시 Z Flip7 | H22: =B22 -> 1485000 | I22: 슬림4G | J22: 33K~49K미만 | K22: 350000 | L22: 350000 | M22: 350000
A23: SM-F966NK | B23: =VLOOKUP($A23,출고가!$C:$E,3,FALSE) -> 2379300 | C23: =A23&I23 -> SM-F966NK베이직 | D23: 삼성 | E23: 5G | F23: =A23 -> SM-F966NK | G23: =VLOOKUP(F23,[1]출고가!C:D,2,0) -> 갤럭시 Z Fold7 | H23: =B23 -> 2379300 | I23: 베이직 | J23: 80K이상 | K23: 580000 | L23: 580000 | M23: 580000
A24: SM-F966NK | B24: =VLOOKUP($A24,출고가!$C:$E,3,FALSE) -> 2379300 | C24: =A24&I24 -> SM-F966NK심플30G | D24: 삼성 | E24: 5G | F24: =A24 -> SM-F966NK | G24: =VLOOKUP(F24,[1]출고가!C:D,2,0) -> 갤럭시 Z Fold7 | H24: =B24 -> 2379300 | I24: 심플30G | J24: 61K~80K미만 | K24: 530000 | L24: 530000 | M24: 530000
A25: SM-F966NK | B25: =VLOOKUP($A25,출고가!$C:$E,3,FALSE) -> 2379300 | C25: =A25&I25 -> SM-F966NK슬림10G | D25: 삼성 | E25: 5G | F25: =A25 -> SM-F966NK | G25: =VLOOKUP(F25,[1]출고가!C:D,2,0) -> 갤럭시 Z Fold7 | H25: =B25 -> 2379300 | I25: 슬림10G | J25: 49K~61K미만 | K25: 480000 | L25: 480000 | M25: 480000
A26: SM-F966NK | B26: =VLOOKUP($A26,출고가!$C:$E,3,FALSE) -> 2379300 | C26: =A26&I26 -> SM-F966NK슬림4G | D26: 삼성 | E26: 5G | F26: =A26 -> SM-F966NK | G26: =VLOOKUP(F26,[1]출고가!C:D,2,0) -> 갤럭시 Z Fold7 | H26: =B26 -> 2379300 | I26: 슬림4G | J26: 33K~49K미만 | K26: 350000 | L26: 350000 | M26: 350000
A27: SM-S937NK | B27: =VLOOKUP($A27,출고가!$C:$E,3,FALSE) -> 1496000 | C27: =A27&I27 -> SM-S937NK베이직 | D27: 삼성 | E27: 5G | F27: =A27 -> SM-S937NK | G27: =VLOOKUP(F27,출고가!C:D,2,0) -> 갤럭시S25 엣지 (256GB) | H27: =B27 -> 1496000 | I27: 베이직 | J27: 80K이상 | K27: 580000 | L27: 580000 | M27: 580000
A28: SM-S937NK | B28: =VLOOKUP($A28,출고가!$C:$E,3,FALSE) -> 1496000 | C28: =A28&I28 -> SM-S937NK심플30G | D28: 삼성 | E28: 5G | F28: =A28 -> SM-S937NK | G28: =VLOOKUP(F28,출고가!C:D,2,0) -> 갤럭시S25 엣지 (256GB) | H28: =B28 -> 1496000 | I28: 심플30G | J28: 61K~80K미만 | K28: 530000 | L28: 530000 | M28: 530000
A29: SM-S937NK | B29: =VLOOKUP($A29,출고가!$C:$E,3,FALSE) -> 1496000 | C29: =A29&I29 -> SM-S937NK슬림10G | D29: 삼성 | E29: 5G | F29: =A29 -> SM-S937NK | G29: =VLOOKUP(F29,출고가!C:D,2,0) -> 갤럭시S25 엣지 (256GB) | H29: =B29 -> 1496000 | I29: 슬림10G | J29: 49K~61K미만 | K29: 480000 | L29: 480000 | M29: 480000
A30: SM-S937NK | B30: =VLOOKUP($A30,출고가!$C:$E,3,FALSE) -> 1496000 | C30: =A30&I30 -> SM-S937NK슬림4G | D30: 삼성 | E30: 5G | F30: =A30 -> SM-S937NK | G30: =VLOOKUP(F30,출고가!C:D,2,0) -> 갤럭시S25 엣지 (256GB) | H30: =B30 -> 1496000 | I30: 슬림4G | J30: 33K~49K미만 | K30: 350000 | L30: 350000 | M30: 350000
A31: SM-S931NK | B31: =VLOOKUP($A31,출고가!$C:$E,3,FALSE) -> 1155000 | C31: =A31&I31 -> SM-S931NK베이직 | D31: 삼성 | E31: 5G | F31: =A31 -> SM-S931NK | G31: =VLOOKUP(F31,출고가!C:D,2,0) -> 갤럭시S25 (256GB) | H31: =B31 -> 1155000 | I31: 베이직 | J31: 80K이상 | K31: 580000 | L31: 580000 | M31: 580000
A32: SM-S931NK | B32: =VLOOKUP($A32,출고가!$C:$E,3,FALSE) -> 1155000 | C32: =A32&I32 -> SM-S931NK심플30G | D32: 삼성 | E32: 5G | F32: =A32 -> SM-S931NK | G32: =VLOOKUP(F32,출고가!C:D,2,0) -> 갤럭시S25 (256GB) | H32: =B32 -> 1155000 | I32: 심플30G | J32: 61K~80K미만 | K32: 530000 | L32: 530000 | M32: 530000
A33: SM-S931NK | B33: =VLOOKUP($A33,출고가!$C:$E,3,FALSE) -> 1155000 | C33: =A33&I33 -> SM-S931NK슬림10G | D33: 삼성 | E33: 5G | F33: =A33 -> SM-S931NK | G33: =VLOOKUP(F33,출고가!C:D,2,0) -> 갤럭시S25 (256GB) | H33: =B33 -> 1155000 | I33: 슬림10G | J33: 49K~61K미만 | K33: 480000 | L33: 480000 | M33: 480000
A34: SM-S931NK | B34: =VLOOKUP($A34,출고가!$C:$E,3,FALSE) -> 1155000 | C34: =A34&I34 -> SM-S931NK슬림4G | D34: 삼성 | E34: 5G | F34: =A34 -> SM-S931NK | G34: =VLOOKUP(F34,출고가!C:D,2,0) -> 갤럭시S25 (256GB) | H34: =B34 -> 1155000 | I34: 슬림4G | J34: 33K~49K미만 | K34: 350000 | L34: 350000 | M34: 350000
A35: SM-S936NK | B35: =VLOOKUP($A35,출고가!$C:$E,3,FALSE) -> 1353000 | C35: =A35&I35 -> SM-S936NK베이직 | D35: 삼성 | E35: 5G | F35: =A35 -> SM-S936NK | G35: =VLOOKUP(F35,출고가!C:D,2,0) -> 갤럭시S25+ (256GB) | H35: =B35 -> 1353000 | I35: 베이직 | J35: 80K이상 | K35: 580000 | L35: 580000 | M35: 580000
A36: SM-S936NK | B36: =VLOOKUP($A36,출고가!$C:$E,3,FALSE) -> 1353000 | C36: =A36&I36 -> SM-S936NK심플30G | D36: 삼성 | E36: 5G | F36: =A36 -> SM-S936NK | G36: =VLOOKUP(F36,출고가!C:D,2,0) -> 갤럭시S25+ (256GB) | H36: =B36 -> 1353000 | I36: 심플30G | J36: 61K~80K미만 | K36: 530000 | L36: 530000 | M36: 530000
A37: SM-S936NK | B37: =VLOOKUP($A37,출고가!$C:$E,3,FALSE) -> 1353000 | C37: =A37&I37 -> SM-S936NK슬림10G | D37: 삼성 | E37: 5G | F37: =A37 -> SM-S936NK | G37: =VLOOKUP(F37,출고가!C:D,2,0) -> 갤럭시S25+ (256GB) | H37: =B37 -> 1353000 | I37: 슬림10G | J37: 49K~61K미만 | K37: 480000 | L37: 480000 | M37: 480000
A38: SM-S936NK | B38: =VLOOKUP($A38,출고가!$C:$E,3,FALSE) -> 1353000 | C38: =A38&I38 -> SM-S936NK슬림4G | D38: 삼성 | E38: 5G | F38: =A38 -> SM-S936NK | G38: =VLOOKUP(F38,출고가!C:D,2,0) -> 갤럭시S25+ (256GB) | H38: =B38 -> 1353000 | I38: 슬림4G | J38: 33K~49K미만 | K38: 350000 | L38: 350000 | M38: 350000
... A63: SM-A175NK | B63: =VLOOKUP($A63,출고가!$C:$E,3,FALSE) -> 319000 | C63: =A63&I63 -> SM-A175NK데이터ON 프리미엄 | D63: 삼성 | E63: LTE | F63: =A63 -> SM-A175NK | G63: =VLOOKUP(F63,출고가!C:D,2,0) -> 갤럭시 A17 | H63: =B63 -> 319000 | I63: 데이터ON 프리미엄 | J63: 49K이상 | K63: 300000 | L63: 300000 | M63: 300000
A64: SM-A165NK | B64: =VLOOKUP($A64,출고가!$C:$E,3,FALSE) -> 319000 | C64: =A64&I64 -> SM-A165NK | D64: 삼성
...

Sheet 공시지원금
B1: ■ 공시 지원금 (3.21일~) | E1: 3 | G1: 68 | H1: 67 | I1: 66 | J1: 65 | K1: 64 | L1: 57 | M1: 48 | N1: 41 | O1: 35 | P1: 33 | Q1: 32 | R1: 24 | S1: 19 | T1: 15 | U1: 11 | V1: 7
B2: 5G/LTE 구분 | C2: 모델명 | D2: 펫네임 | E2: 출고가 | F2: 지원금 구분 | G2: 요금제별 지원금
G3: 초이스 프리미엄 | H3: 초이스 스페셜 | I3: 스페셜 | J3: 초이스 베이직 ON 프리미엄 | K3: 베이직 | L3: 5G 심플 110G ON 비디오 | M3: 5G 슬림 플러스 LTE 슬림 플러스 | N3: 5G 슬림 | O3: ON 톡 | P3: 5G Y틴 | Q3: 5G 세이브 | R3: 5G 주니어 | S3: LTE 베이직 | T3: 5G 주니어 슬림 LTE 주니어 슬림 | U3: Y주니어ON | V3: Y주니어19.8
B4: ※ 요금할인(지원금) 25% + vat. | G4: 780000 | H4: 660000 | I4: 600000 | J4: 540000 | K4: 480000 | L4: 414000 | M4: 366000 | N4: 330000 | O4: 294000 | P4: 282000 | Q4: 270000 | R4: 228000 | S4: 198000 | T4: 153600 | U4: 144000 | V4: 118800
B5: 5G | C5: MI-RMN12P5GK | D5: 샤오미 레드미 노트 12 Pro Plus 5G | E5: 599500 | F5: 공시지원금 | G5: 350000 | H5: 350000 | I5: 350000 | J5: 350000 | K5: 350000 | L5: 350000 | M5: 350000 | N5: 350000 | O5: 350000 | P5: 350000 | Q5: 350000 | R5: 350000 | S5: 350000 | T5: 350000 | U5: 350000 | V5: 350000
F6: MNP 전환 지원금 | G6: 0 | H6: 0 | I6: 0 | J6: 0 | K6: 0 | L6: 0 | M6: 0 | N6: 0 | O6: 0 | P6: 0 | Q6: 0 | R6: 0 | S6: 0 | T6: 0 | U6: 0 | V6: 0
B7: LTE | C7: SM-A155NK | D7: 갤럭시 A15 | E7: 319000 | F7: 공시지원금 | G7: 234000 | H7: 234000 | I7: 234000 | J7: 234000 | K7: 234000 | L7: 234000 | M7: 234000 | N7: 234000 | O7: 234000 | P7: 234000 | Q7: 234000 | R7: 234000 | S7: 234000 | T7: 234000 | U7: 234000 | V7: 234000
F8: MNP 전환 지원금 | G8: 50000 | H8: 50000 | I8: 50000 | J8: 50000 | K8: 50000 | L8: 50000 | M8: 50000 | N8: 50000 | O8: 50000 | P8: 50000 | Q8: 50000 | R8: 50000 | S8: 50000 | T8: 50000 | U8: 50000 | V8: 50000
B9: LTE | C9: AT-M130K | D9: 시나모롤 키즈폰 | E9: 320100 | F9: 공시지원금 | G9: 275000 | H9: 275000 | I9: 275000 | J9: 275000 | K9: 275000 | L9: 275000 | M9: 275000 | N9: 275000 | O9: 275000 | P9: 275000 | Q9: 275000 | R9: 275000 | S9: 275000 | T9: 275000 | U9: 275000 | V9: 275000
F10: MNP 전환 지원금 | G10: 0 | H10: 0 | I10: 0 | J10: 0 | K10: 0 | L10: 0 | M10: 0 | N10: 0 | O10: 0 | P10: 0 | Q10: 0 | R10: 0 | S10: 0 | T10: 0 | U10: 0 | V10: 0

Sheet 정책적용 요금제_LTE
A1: ■ 정책 적용 요금제 List_(공통/24.5.1~)
A3: (공통) 33K 미만 정책 대상 List | D3: (공통) 33K 이상 정책 대상 List | F3: (공통) 37K 이상 정책 대상 List | H3: (공통) 44K 이상 정책 대상 List | J3: (공통) 49K 이상 정책 대상 List | L3: (공통) 55K 이상 정책 대상 List | N3: (공통) 61K 이상 정책 대상 List | P3: (공통) 69K 이상 정책 대상 List | R3: (공통) 80K 이상 정책 대상 List | T3: (공통) 90K 이상 정책 대상 List | V3: (공통) 100K 이상 정책 대상 List | X3: (공통) 110K 이상 정책 대상 List
A4: 요금제명 | B4: 요금제ID | D4: 요금제명 | E4: 요금제ID | F4: 요금제명 | G4: 요금제ID | J4: 요금제명 | K4: 요금제ID | L4: 요금제명 | M4: 요금제ID | N4: 요금제명 | O4: 요금제ID | P4: 요금제명 | Q4: 요금제ID | R4: 요금제명 | S4: 요금제ID | T4: 요금제명 | U4: 요금제ID | V4: 요금제명 | W4: 요금제ID | X4: 요금제명 | Y4: 요금제ID
A5: LTE 음성 18.7 | B5: LTENDT198 | D5: 5G 슬림 14GB | E5: 5GINTMPP2 | F5: 5G 슬림 14GB | G5: 5GINTMPP2 | H5: 5G 슬림 14GB | I5: 5GINTMPP2 | J5: 5G 슬림 14GB | K5: 5GINTMPP2 | L5: 5G 슬림 14GB | M5: 5GINTMPP2 | N5: 베이직 | O5: 5GINTMPP3 | P5: 베이직 | Q5: 5GINTMPP3 | R5: 베이직 | S5: 5GINTMPP3 | T5: 스페셜 | U5: 5GINTMPP4 | V5: 스페셜 | W5: 5GINTMPP4 | X5: 넷플릭스 초이스 스페셜 | Y5: PL208A884
A6: LTE-골든150(안심차단) | B6: LTEPIG150 | D6: 5G 슬림(이월) 14GB | E6: PL23B1938 | F6: 5G 슬림(이월) 14GB | G6: PL23B1938 | H6: 5G 슬림(이월) 14GB | I6: PL23B1938 | J6: 5G 슬림(이월) 14GB | K6: PL23B1938 | L6: 5G 슬림(이월) 14GB | M6: PL23B1938 | N6: 스페셜 | O6: 5GINTMPP4 | P6: 스페셜 | Q6: 5GINTMPP4 | R6: 스페셜 | S6: 5GINTMPP4 | T6: 5G Y 스페셜 | U6: PL19CB587 | V6: 5G Y 스페셜 | W6: PL19CB587 | X6: 넷플릭스 초이스 프리미엄 | Y6: PL208A888
A7: LTE-골든150 | B7: LTERAG150 | D7: 5G 슬림(군인) | E7: PL21CL673 | F7: 5G 슬림(군인) | G7: PL21CL673 | H7: 5G 슬림(군인) | I7: PL21CL673 | J7: 5G 슬림(군인) | K7: PL21CL673 | L7: 5G 슬림(군인) | M7: PL21CL673 | N7: 5G 심플 110GB | O7: 5GINTMPP7 | P7: 5G 심플 110GB | Q7: 5GINTMPP7 | R7: 5G Y 스페셜 | S7: PL19CB587 | T7: 넷플릭스 초이스 스페셜 | U7: PL208A884 | V7: 넷플릭스 초이스 스페셜 | W7: PL208A884 | X7: 현대카드 초이스 스페셜 | Y7: PL2146251
A8: 키즈 알115(LTE) | B8: LTESLVBGR | D8: 베이직 | E8: 5GINTMPP3 | F8: 베이직 | G8: 5GINTMPP3 | H8: 베이직 | I8: 5GINTMPP3 | J8: 베이직 | K8: 5GINTMPP3 | L8: 베이직 | M8: 5GINTMPP3 | N8: 5G 심플 90GB | O8: PL234D608 | P8: 5G Y 스페셜 | Q8: PL19CB587 | R8: 5G Y 베이직 | S8: PL19CB588 | T8: 넷플릭스 초이스 프리미엄 | U8: PL208A888 | V8: 넷플릭스 초이스 프리미엄 | W8: PL208A888 | X8: 현대카드 초이스 프리미엄 | Y8: PL2146252
A9: LTE 음성 12.1 | B9: LTESTNDRD | D9: 스페셜 | E9: 5GINTMPP4 | F9: 스페셜 | G9: 5GINTMPP4 | H9: 스페셜 | I9: 5GINTMPP4 | J9: 스페셜 | K9: 5GINTMPP4 | L9: 스페셜 | M9: 5GINTMPP4 | N9: 5G 심플 70GB | O9: PL234D607 | P9: 5G Y 베이직 | Q9: PL19CB588 | R9: 넷플릭스 초이스 스페셜 | S9: PL208A884 | T9: 넷플릭스 초이스 베이직 | U9: PL208A889 | V9: 현대카드 초이스 스페셜 | W9: PL2146251 | X9: 디즈니+ 초이스 프리미엄 | Y9: PL218N859
A10: 순 LTE선택형100분250MB | B10: SELECSA01 | D10: 5G 심플 | E10: 5GINTMPP7 | F10: 5G 심플 | G10: 5GINTMPP7 | H10: 5G 심플 | I10: 5GINTMPP7 | J10: 5G 심플 | K10: 5GINTMPP7 | L10: 5G 심플 | M10: 5GINTMPP7 | N10: 5G 심플 50GB | O10: PL234D606 | P10: 넷플릭스 초이스 스페셜 | Q10: PL208A884 | R10: 넷플릭스 초이스 프리미엄 | S10: PL208A888 | T10: 현대카드 초이스 베이직 | U10: PL2146250 | V10: 현대카드 초이스 프리미엄 | W10: PL2146252 | X10: 디즈니+ 초이스 스페셜 | Y10: PL218N866
A11: 순 LTE선택형100분1GB | B11: SELECSA02 | D11: 5G 심플 90GB | E11: PL234D608 | F11: 5G 심플 90GB | G11: PL234D608 | H11: 5G 심플 90GB | I11: PL234D608 | J11: 5G 심플 90GB | K11: PL234D608 | L11: 5G 심플 90GB | M11: PL234D608 | N11: 5G Y 스페셜 | O11: PL19CB587 | P11: 넷플릭스 초이스 프리미엄 | Q11: PL208A888 | R11: 넷플릭스 초이스 베이직 | S11: PL208A889 | T11: 현대카드 초이스 스페셜 | U11: PL2146251 | V11: 디즈니+ 초이스 프리미엄 | W11: PL218N859 | X11: 삼성 초이스 프리미엄 | Y11: PL21C9618
A12: 순 LTE선택형100분2GB | B12: SELECSA03 | D12: 5G 심플 70GB | E12: PL234D607 | F12: 5G 심플 70GB | G12: PL234D607 | H12: 5G 심플 70GB | I12: PL234D607 | J12: 5G 심플 70GB | K12: PL234D607 | L12: 5G 심플 70GB | M12: PL234D607 | N12: 5G Y 베이직 | O12: PL19CB588 | P12: 넷플릭스 초이스 베이직 | Q12: PL208A889 | R12: 5G 베이직 복지 | S12: PL2128869 | T12: 현대카드 초이스 프리미엄 | U12: PL2146252 | V12: 디즈니+ 초이스 스페셜 | W12: PL218N866 | X12: 삼성 초이스 스페셜 | Y12: PL21C9617
A13: 순 LTE선택형180분250MB | B13: SELECSB01 | D13: 5G 심플 50GB | E13: PL234D606 | F13: 5G 심플 50GB | G13: PL234D606 | H13: 5G 심플 50GB | I13: PL234D606 | J13: 5G 심플 50GB | K13: PL234D606 | L13: 5G 심플 50GB | M13: PL234D606 | N13: 넷플릭스 초이스 스페셜 | O13: PL208A884 | P13: 5G 베이직 복지 | Q13: PL2128869 | R13: 현대카드 초이스 베이직 | S13: PL2146250 | T13: 디즈니+ 초이스 프리미엄 | U13: PL218N859 | V13: 삼성 초이스 프리미엄 | W13: PL21C9618 | X13: 우리카드 초이스 프리미엄 | Y13: PL21CM713
A14: 순 LTE선택형180분1GB | B14: SELECSB02 | D14: 5G Y틴 | E14: 5GINTMPP8 | F14: 5G Y틴 | G14: 5GINTMPP8 | H14: 5G Y틴 | I14: 5GINTMPP8 | J14: 5G Y틴 | K14: 5GINTMPP8 | L14: 5G Y틴 | M14: 5GINTMPP8 | N14: 넷플릭스 초이스 프리미엄 | O14: PL208A888 | P14: 현대카드 초이스 베이직 | Q14: PL2146250 | R14: 현대카드 초이스 스페셜 | S14: PL2146251 | T14: 디즈니+ 초이스 스페셜 | U14: PL218N866 | V14: 삼성 초이스 스페셜 | W14: PL21C9617 | X14: 우리카드 초이스 스페셜 | Y14: PL21CM720
A15: 순 망내무한선택형100분250MB | B15: SELECSF01 | D15: 5G Y 스페셜 | E15: PL19CB587 | F15: 5G Y 스페셜 | G15: PL19CB587 | H15: 5G Y 스페셜 | I15: PL19CB587 | J15: 5G Y 스페셜 | K15: PL19CB587 | L15: 5G Y 스페셜 | M15: PL19CB587 | N15: 넷플릭스 초이스 베이직 | O15: PL208A889 | P15: 현대카드 초이스 스페셜 | Q15: PL2146251 | R15: 현대카드 초이스 프리미엄 | S15: PL2146252 | T15: 디즈니+ 초이스 베이직 | U15: PL218N869 | V15: 우리카드 초이스 프리미엄 | W15: PL21CM713 | X15: (유튜브 프리미엄) 초이스 프리미엄 | Y15: PL241V593
A16: 순 망내무한선택형100분1GB | B16: SELECSF02 | D16: 5G Y 베이직 | E16: PL19CB588 | F16: 5G Y 베이직 | G16: PL19CB588 | H16: 5G Y 베이직 | I16: PL19CB588 | J16: 5G Y 베이직 | K16: PL19CB588 | L16: 5G Y 베이직 | M16: PL19CB588 | N16: 5G 베이직 복지 | O16: PL2128869 | P16: 현대카드 초이스 프리미엄 | Q16: PL2146252 | R16: 디즈니+ 초이스 프리미엄 | S16: PL218N859 | T16: 삼성 초이스 프리미엄 | U16: PL21C9618 | V16: 우리카드 초이스 스페셜 | W16: PL21CM720 | X16: (유튜브 프리미엄) 초이스 스페셜 | Y16: PL241V594
... A18: Y주니어 19.8(LTE) | B18: YJUNRLTE1 | D18: 5G Y슬림(군인) | E18: PL21CL661 | F18: 5G Y슬림(군인) | G18: PL21CL661 | H18: 5G Y슬림(군인) | I18: PL21CL661 | J18: 5G Y슬림(군인) | K18: PL21CL661 | L18: 5G Y슬림(군인) | M18: PL21CL661 | N18: 현대카드 초이스 스페셜 | O18: PL2146251 | P18: 디즈니+ 초이스 프리미엄 | Q18: PL218N859 | R18: 디즈니+ 초이스 베이직 | S18: PL218N869 | T18: 삼성 초이스 베이직 | U18: PL21C9619 | V18: (유튜브 프리미엄) 초이스 스페셜 | W18: PL241V594 | X18: 디바이스 초이스 스페셜 | Y18: PL221A794
D19: 넷플릭스 초이스 스페셜 | E19: PL208A884 | F19: 넷플릭스 초이스 스페셜 | G19: PL208A884 | H19: 넷플릭스 초이스 스페셜 | I19: PL208A884 | J19: 넷플릭스 초이스 스페셜 | K19: PL208A884 | L19: 넷플릭스 초이스 스페셜 | M19: PL208A884 | N19: 현대카드 초이스 프리미엄 | O19: PL2146252 | P19: 디즈니+ 초이스 스페셜 | Q19: PL218N866 | R19: 삼성 초이스 프리미엄 | S19: PL21C9618 | T19: 우리카드 초이스 프리미엄 | U19: PL21CM713 | V19: 디바이스 초이스 프리미엄 | W19: PL221A793 | X19: 티빙/지니 초이스 프리미엄 | Y19: PL225O787
D20: 넷플릭스 초이스 프리미엄 | E20: PL208A888 | F20: 넷플릭스 초이스 프리미엄 | G20: PL208A888 | H20: 넷플릭스 초이스 프리미엄 | I20: PL208A888 | J20: 넷플릭스 초이스 프리미엄 | K20: PL208A888 | L20: 넷플릭스 초이스 프리미엄 | M20: PL208A888 | N20: 5G 심플 복지 | O20: PL2154385 | P20: 디즈니+ 초이스 베이직 | Q20: PL218N869 | R20: 삼성 초이스 스페셜 | S20: PL21C9617 | T20: 우리카드 초이스 스페셜 | U20: PL21CM720 | V20: 디바이스 초이스 스페셜 | W20: PL221A794 | X20: 티빙/지니 초이스 스페셜 | Y20: PL225O788
D21: 넷플릭스 초이스 베이직 | E21: PL208A889 | F21: 넷플릭스 초이스 베이직 | G21: PL208A889 | H21: 넷플릭스 초이스 베이직 | I21: PL208A889 | J21: 넷플릭스 초이스 베이직 | K21: PL208A889 | L21: 넷플릭스 초이스 베이직 | M21: PL208A889 | N21: 디즈니+ 초이스 프리미엄 | O21: PL218N859 | P21: 삼성 초이스 프리미엄 | Q21: PL21C9618 | R21: 삼성 초이스 베이직 | S21: PL21C9619 | T21: 우리카드 초이스 베이직 | U21: PL21CM718 | V21: 티빙/지니 초이스 프리미엄 | W21: PL225O787 | X21: BC바로 카드 초이스 프리미엄 | Y21: PL225O770
D22: 5G 슬림 7GB | E22: PL2093132 | F22: 5G 슬림 7GB | G22: PL2093132 | H22: 5G 슬림 7GB | I22: PL2093132 | J22: 5G 슬림 복지 | K22: PL2128868 | L22: 5G 슬림 복지 | M22: PL2128868 | N22: 디즈니+ 초이스 스페셜 | O22: PL218N866 | P22: 삼성 초이스 스페셜 | Q22: PL21C9617 | R22: 우리카드 초이스 프리미엄 | S22: PL21CM713 | T22: (유튜브 프리미엄) 초이스 프리미엄 | U22: PL241V593 | V22: 티빙/지니 초이스 스폐셜 | W22: PL225O788 | X22: BC바로 카드 초이스 스페셜 | Y22: PL225O772
D23: 5G 슬림(이월) 7GB | E23: PL23B1935 | F23: 5G 슬림(이월) 7GB | G23: PL23B1935 | H23: 5G 슬림(이월) 7GB | I23: PL23B1935 | J23: 5G 슬림 복지(군인) | K23: PL21CL671 | L23: 5G 슬림 복지(군인) | M23: PL21CL671 | N23: 디즈니+ 초이스 베이직 | O23: PL218N869 | P23: 삼성 초이스 베이직 | Q23: PL21C9619 | R23: 우리카드 초이스 스페셜 | S23: PL21CM720 | T23: (유튜브 프리미엄) 초이스 스페셜 | U23: PL241V594 | V23: BC바로 카드 초이스 프리미엄 | W23: PL225O770 | X23: 코웨이 초이스 프리미엄 | Y23: PL2193924
D24: 5G 세이브(군인) | E24: PL21CL674 | F24: 5G 세이브(군인) | G24: PL21CL674 | H24: 5G 세이브(군인) | I24: PL21CL674 | J24: 5G 베이직 복지 | K24: PL2128869 | L24: 5G 베이직 복지 | M24: PL2128869 | N24: 삼성 초이스 프리미엄 | O24: PL21C9618 | P24: 우리카드 초이스 프리미엄 | Q24: PL21CM713 | R24: 우리카드 초이스 베이직 | S24: PL21CM718 | T24: (유튜브 프리미엄) 초이스 베이직 | U24: PL241V595 | V24: BC바로 카드 초이스 스페셜 | W24: PL225O772 | X24: 코웨이 초이스 스페셜 | Y24: PL2193928
D25: 5G 슬림 복지 | E25: PL2128868 | F25: 5G 슬림 복지 | G25: PL2128868 | H25: 5G 슬림 복지 | I25: PL2128868 | J25: 현대카드 초이스 베이직 | K25: PL2146250 | L25: 현대카드 초이스 베이직 | M25: PL2146250 | N25: 삼성 초이스 스페셜 | O25: PL21C9617 | P25: 우리카드 초이스 스페셜 | Q25: PL21CM720 | R25: (유튜브 프리미엄) 초이스 프리미엄 | S25: PL241V593 | T25: 디바이스 초이스 프리미엄 | U25: PL221A793 | V25: 코웨이 초이스 프리미엄 | W25: PL2193924 | X25: 티빙/밀리 초이스 프리미엄 | Y25: PL22BO519
D26: 5G 슬림 복지(군인) | E26: PL21CL671 | F26: 5G 슬림 복지(군인) | G26: PL21CL671 | H26: 5G 슬림 복지(군인) | I26: PL21CL671 | J26: 현대카드 초이스 스페셜 | K26: PL2146251 | L26: 현대카드 초이스 스페셜 | M26: PL2146251 | N26: 삼성 초이스 베이직 | O26: PL21C9619 | P26: 우리카드 초이스 베이직 | Q26: PL21CM718 | R26: (유튜브 프리미엄) 초이스 스페셜 | S26: PL241V594 | T26: 디바이스 초이스 스페셜 | U26: PL221A794 | V26: 코웨이 초이스 스페셜 | W26: PL2193928 | X26: 티빙/밀리 초이스 스페셜 | Y26: PL22BO525
D27: 5G 베이직 복지 | E27: PL2128869 | F27: 5G 베이직 복지 | G27: PL2128869 | H27: 5G 베이직 복지 | I27: PL2128869 | J27: 현대카드 초이스 프리미엄 | K27: PL2146252 | L27: 현대카드 초이스 프리미엄 | M27: PL2146252 | N27: 우리카드 초이스 프리미엄 | O27: PL21CM713 | P27: (유튜브 프리미엄) 초이스 프리미엄 | Q27: PL241V593 | R27: (유튜브 프리미엄) 초이스 베이직 | S27: PL241V595 | T27: 디바이스 초이스 베이직 | U27: PL221A795 | V27: 티빙/밀리 초이스 프리미엄 | W27: PL22BO519
D28: 현대카드 초이스 베이직 | E28: PL2146250 | F28: 현대카드 초이스 베이직 | G28: PL2146250 | H28: 현대카드 초이스 베이직 | I28: PL2146250 | J28: 5G 심플 복지 | K28: PL2154385 | L28: 5G 심플 복지 | M28: PL2154385 | N28: 우리카드 초이스 스페셜 | O28: PL21CM720 | P28: (유튜브 프리미엄) 초이스 스페셜 | Q28: PL241V594 | R28: 디바이스 초이스 프리미엄 | S28: PL221A793 | T28: 티빙/지니 초이스 프리미엄 | U28: PL225O787 | V28: 티빙/밀리 초이스 스페셜 | W28: PL22BO525
D29: 현대카드 초이스 스페셜 | E29: PL2146251 | F29: 현대카드 초이스 스페셜 | G29: PL2146251 | H29: 현대카드 초이스 스페셜 | I29: PL2146251 | J29: 디즈니+ 초이스 프리미엄 | K29: PL218N859 | L29: 디즈니+ 초이스 프리미엄 | M29: PL218N859 | N29: 우리카드 초이스 베이직 | O29: PL21CM718 | P29: (유튜브 프리미엄) 초이스 베이직 | Q29: PL241V595 | R29: 디바이스 초이스 스페셜 | S29: PL221A794 | T29: 티빙/지니 초이스 스폐셜 | U29: PL225O788
D30: 현대카드 초이스 프리미엄 | E30: PL2146252 | F30: 현대카드 초이스 프리미엄 | G30: PL2146252 | H30: 현대카드 초이스 프리미엄 | I30: PL2146252 | J30: 디즈니+ 초이스 스페셜 | K30: PL218N866 | L30: 디즈니+ 초이스 스페셜 | M30: PL218N866 | N30: (유튜브 프리미엄) 초이스 프리미엄 | O30: PL241V593 | P30: 디바이스 초이스 프리미엄 | Q30: PL221A793 | R30: 디바이스 초이스 베이직 | S30: PL221A795 | T30: 티빙/지니 초이스 베이직 | U30: PL225O789
D31: 5G 심플 복지 | E31: PL2154385 | F31: 5G 심플 복지 | G31: PL2154385 | H31: 5G 심플 복지 | I31: PL2154385 | J31: 디즈니+ 초이스 베이직 | K31: PL218N869 | L31: 디즈니+ 초이스 베이직 | M31: PL218N869 | N31: (유튜브 프리미엄) 초이스 스페셜 | O31: PL241V594 | P31: 디바이스 초이스 스페셜 | Q31: PL221A794 | R31: 티빙/지니 초이스 프리미엄 | S31: PL225O787 | T31: BC바로 카드 초이스 프리미엄 | U31: PL225O770
D32: 디즈니+ 초이스 프리미엄 | E32: PL218N859 | F32: 디즈니+ 초이스 프리미엄 | G32: PL218N859 | H32: 디즈니+ 초이스 프리미엄 | I32: PL218N859 | J32: 삼성 초이스 프리미엄 | K32: PL21C9618 | L32: 삼성 초이스 프리미엄 | M32: PL21C9618 | N32: (유튜브 프리미엄) 초이스 베이직 | O32: PL241V595 | P32: 디바이스 초이스 베이직 | Q32: PL221A795 | R32: 티빙/지니 초이스 스폐셜 | S32: PL225O788 | T32: BC바로 카드 초이스 스페셜 | U32: PL225O772
D33: 디즈니+ 초이스 스페셜 | E33: PL218N866 | F33: 디즈니+ 초이스 스페셜 | G33: PL218N866 | H33: 디즈니+ 초이스 스페셜 | I33: PL218N866 | J33: 삼성 초이스 스페셜 | K33: PL21C9617 | L33: 삼성 초이스 스페셜 | M33: PL21C9617 | N33: 디바이스 초이스 프리미엄 | O33: PL221A793 | P33: 티빙/지니 초이스 프리미엄 | Q33: PL225O787 | R33: 티빙/지니 초이스 베이직 | S33: PL225O789 | T33: BC바로 카드 초이스 베이직 | U33: PL225O773
D34: 디즈니+ 초이스 베이직 | E34: PL218N869 | F34: 디즈니+ 초이스 베이직 | G34: PL218N869 | H34: 디즈니+ 초이스 베이직 | I34: PL218N869 | J34: 삼성 초이스 베이직 | K34: PL21C9619 | L34: 삼성 초이스 베이직 | M34: PL21C9619 | N34: 디바이스 초이스 스페셜 | O34: PL221A794 | P34: 티빙/지니 초이스 스폐셜 | Q34: PL225O788 | R34: BC바로 카드 초이스 프리미엄 | S34: PL225O770 | T34: 코웨이 초이스 프리미엄 | U34: PL2193924
D35: 삼성 초이스 프리미엄 | E35: PL21C9618 | F35: 삼성 초이스 프리미엄 | G35: PL21C9618 | H35: 삼성 초이스 프리미엄 | I35: PL21C9618 | J35: 우리카드 초이스 프리미엄 | K35: PL21CM713 | L35: 우리카드 초이스 프리미엄 | M35: PL21CM713 | N35: 디바이스 초이스 베이직 | O35: PL221A795 | P35: 티빙/지니 초이스 베이직 | Q35: PL225O789 | R35: BC바로 카드 초이스 스페셜 | S35: PL225O772 | T35: 코웨이 초이스 스페셜 | U35: PL2193928
D36: 삼성 초이스 스페셜 | E36: PL21C9617 | F36: 삼성 초이스 스페셜 | G36: PL21C9617 | H36: 삼성 초이스 스페셜 | I36: PL21C9617 | J36: 우리카드 초이스 스페셜 | K36: PL21CM720 | L36: 우리카드 초이스 스페셜 | M36: PL21CM720 | N36: 티빙/지니 초이스 프리미엄 | O36: PL225O787 | P36: BC바로 카드 초이스 프리미엄 | Q36: PL225O770 | R36: BC바로 카드 초이스 베이직 | S36: PL225O773 | T36: 코웨이 초이스 베이직 | U36: PL2193929
D37: 삼성 초이스 베이직 | E37: PL21C9619 | F37: 삼성 초이스 베이직 | G37: PL21C9619 | H37: 삼성 초이스 베이직 | I37: PL21C9619 | J37: 우리카드 초이스 베이직 | K37: PL21CM718 | L37: 우리카드 초이스 베이직 | M37: PL21CM718 | N37: 티빙/지니 초이스 스폐셜 | O37: PL225O788 | P37: BC바로 카드 초이스 스페셜 | Q37: PL225O772 | R37: 코웨이 초이스 프리미엄 | S37: PL2193924 | T37: 티빙/밀리 초이스 프리미엄 | U37: PL22BO519
D38: 우리카드 초이스 프리미엄 | E38: PL21CM713 | F38: 우리카드 초이스 프리미엄 | G38: PL21CM713 | H38: 우리카드 초이스 프리미엄 | I38: PL21CM713 | J38: (유튜브 프리미엄) 초이스 프리미엄 | K38: PL241V593 | L38: (유튜브 프리미엄) 초이스 프리미엄 | M38: PL241V593 | N38: 티빙/지니 초이스 베이직 | O38: PL225O789 | P38: BC바로 카드 초이스 베이직 | Q38: PL225O773 | R38: 코웨이 초이스 스페셜 | S38: PL2193928 | T38: 티빙/밀리 초이스 스페셜 | U38: PL22BO525
D39: 우리카드 초이스 스페셜 | E39: PL21CM720 | F39: 우리카드 초이스 스페셜 | G39: PL21CM720 | H39: 우리카드 초이스 스페셜 | I39: PL21CM720 | J39: (유튜브 프리미엄) 초이스 스페셜 | K39: PL241V594 | L39: (유튜브 프리미엄) 초이스 스페셜 | M39: PL241V594 | N39: BC바로 카드 초이스 프리미엄 | O39: PL225O770 | P39: 코웨이 초이스 프리미엄 | Q39: PL2193924 | R39: 코웨이 초이스 베이직 | S39: PL2193929 | T39: 티빙/밀리 초이스 베이직 | U39: PL22BO527
D40: 우리카드 초이스 베이직 | E40: PL21CM718 | F40: 우리카드 초이스 베이직 | G40: PL21CM718 | H40: 우리카드 초이스 베이직 | I40: PL21CM718 | J40: (유튜브 프리미엄) 초이스 베이직 | K40: PL241V595 | L40: (유튜브 프리미엄) 초이스 베이직 | M40: PL241V595 | N40: BC바로 카드 초이스 스페셜 | O40: PL225O772 | P40: 코웨이 초이스 스페셜 | Q40: PL2193928 | R40: 티빙/밀리 초이스 프리미엄 | S40: PL22BO519 | T40: 데이터 ON 프리미엄 | U40: KDRTLTE90
D41: (유튜브 프리미엄) 초이스 프리미엄 | E41: PL241V593 | F41: (유튜브 프리미엄) 초이스 프리미엄 | G41: PL241V593 | H41: (유튜브 프리미엄) 초이스 프리미엄 | I41: PL241V593 | J41: 디바이스 초이스 프리미엄 | K41: PL221A793 | L41: 디바이스 초이스 프리미엄 | M41: PL221A793 | N41: BC바로 카드 초이스 베이직 | O41: PL225O773 | P41: 코웨이 초이스 베이직 | Q41: PL2193929 | R41: 티빙/밀리 초이스 스페셜 | S41: PL22BO525 | T41: Y데이터 ON 프리미엄 | U41: NWY24LTE3
D42: (유튜브 프리미엄) 초이스 스페셜 | E42: PL241V594 | F42: (유튜브 프리미엄) 초이스 스페셜 | G42: PL241V594 | H42: (유튜브 프리미엄) 초이스 스페셜 | I42: PL241V594 | J42: 디바이스 초이스 스페셜 | K42: PL221A794 | L42: 디바이스 초이스 스페셜 | M42: PL221A794 | N42: 코웨이 초이스 프리미엄 | O42: PL2193924 | P42: 티빙/밀리 초이스 프리미엄 | Q42: PL22BO519 | R42: 티빙/밀리 초이스 베이직 | S42: PL22BO527
...

Sheet 정책적용 요금제_5G
B1: ■ 정책 적용 요금제 List_(5G요금제/24.5.1~)
B3: (공통) 33K 이상 정책 대상 List | D3: (공통) 37K 이상 정책 대상 List | F3: (공통) 49K 이상 정책 대상 List | H3: (공통) 55K 이상 정책 대상 List | J3: (공통) 61K 이상 정책 대상 List | L3: (공통) 69K 이상 정책 대상 List | N3: (공통) 80K 이상 정책 대상 List | P3: (공통) 90K 이상 정책 대상 List | R3: (공통) 100K 이상 정책 대상 List | T3: (공통) 110K 이상 정책 대상 List
B4: 요금제명 | C4: 요금제ID | D4: 요금제명 | E4: 요금제ID | F4: 요금제명 | G4: 요금제ID | H4: 요금제명 | I4: 요금제ID | J4: 요금제명 | K4: 요금제ID | L4: 요금제명 | M4: 요금제ID | N4: 요금제명 | O4: 요금제ID | P4: 요금제명 | Q4: 요금제ID | R4: 요금제명 | S4: 요금제ID | T4: 요금제명 | U4: 요금제ID
B5: 5G 슬림 14GB | C5: 5GINTMPP2 | D5: 5G 슬림 14GB | E5: 5GINTMPP2 | F5: 5G 슬림 14GB | G5: 5GINTMPP2 | H5: 5G 슬림 14GB | I5: 5GINTMPP2 | J5: 베이직 | K5: 5GINTMPP3 | L5: 베이직 | M5: 5GINTMPP3 | N5: 베이직 | O5: 5GINTMPP3 | P5: 스페셜 | Q5: 5GINTMPP4 | R5: 스페셜 | S5: 5GINTMPP4 | T5: 넷플릭스 초이스 스페셜 | U5: PL208A884
B6: 5G 슬림(이월) 14GB | C6: PL23B1938 | D6: 5G 슬림(이월) 14GB | E6: PL23B1938 | F6: 5G 슬림(이월) 14GB | G6: PL23B1938 | H6: 5G 슬림(이월) 14GB | I6: PL23B1938 | J6: 스페셜 | K6: 5GINTMPP4 | L6: 스페셜 | M6: 5GINTMPP4 | N6: 스페셜 | O6: 5GINTMPP4 | P6: 5G Y 스페셜 | Q6: PL19CB587 | R6: 5G Y 스페셜 | S6: PL19CB587 | T6: 넷플릭스 초이스 프리미엄 | U6: PL208A888
B7: 5G 슬림(군인) | C7: PL21CL673 | D7: 5G 슬림(군인) | E7: PL21CL673 | F7: 5G 슬림(군인) | G7: PL21CL673 | H7: 5G 슬림(군인) | I7: PL21CL673 | J7: 5G 심플 110GB | K7: 5GINTMPP7 | L7: 5G 심플 110GB | M7: 5GINTMPP7 | N7: 5G Y 스페셜 | O7: PL19CB587 | P7: 넷플릭스 초이스 스페셜 | Q7: PL208A884 | R7: 넷플릭스 초이스 스페셜 | S7: PL208A884 | T7: 현대카드 초이스 스페셜 | U7: PL2146251
B8: 베이직 | C8: 5GINTMPP3 | D8: 베이직 | E8: 5GINTMPP3 | F8: 베이직 | G8: 5GINTMPP3 | H8: 베이직 | I8: 5GINTMPP3 | J8: 5G 심플 90GB | K8: PL234D608 | L8: 5G Y 스페셜 | M8: PL19CB587 | N8: 5G Y 베이직 | O8: PL19CB588 | P8: 넷플릭스 초이스 프리미엄 | Q8: PL208A888 | R8: 넷플릭스 초이스 프리미엄 | S8: PL208A888 | T8: 현대카드 초이스 프리미엄 | U8: PL2146252
B9: 스페셜 | C9: 5GINTMPP4 | D9: 스페셜 | E9: 5GINTMPP4 | F9: 스페셜 | G9: 5GINTMPP4 | H9: 스페셜 | I9: 5GINTMPP4 | J9: 5G 심플 70GB | K9: PL234D607 | L9: 5G Y 베이직 | M9: PL19CB588 | N9: 넷플릭스 초이스 스페셜 | O9: PL208A884 | P9: 넷플릭스 초이스 베이직 | Q9: PL208A889 | R9: 현대카드 초이스 스페셜 | S9: PL2146251 | T9: 디즈니+ 초이스 프리미엄 | U9: PL218N859
B10: 5G 심플 | C10: 5GINTMPP7 | D10: 5G 심플 | E10: 5GINTMPP7 | F10: 5G 심플 | G10: 5GINTMPP7 | H10: 5G 심플 | I10: 5GINTMPP7 | J10: 5G 심플 50GB | K10: PL234D606 | L10: 넷플릭스 초이스 스페셜 | M10: PL208A884 | N10: 넷플릭스 초이스 프리미엄 | O10: PL208A888 | P10: 현대카드 초이스 베이직 | Q10: PL2146250 | R10: 현대카드 초이스 프리미엄 | S10: PL2146252 | T10: 디즈니+ 초이스 스페셜 | U10: PL218N866
B11: 5G 심플 90GB | C11: PL234D608 | D11: 5G 심플 90GB | E11: PL234D608 | F11: 5G 심플 90GB | G11: PL234D608 | H11: 5G 심플 90GB | I11: PL234D608 | J11: 5G Y 스페셜 | K11: PL19CB587 | L11: 넷플릭스 초이스 프리미엄 | M11: PL208A888 | N11: 넷플릭스 초이스 베이직 | O11: PL208A889 | P11: 현대카드 초이스 스페셜 | Q11: PL2146251 | R11: 디즈니+ 초이스 프리미엄 | S11: PL218N859 | T11: 삼성 초이스 프리미엄 | U11: PL21C9618
B12: 5G 심플 70GB | C12: PL234D607 | D12: 5G 심플 70GB | E12: PL234D607 | F12: 5G 심플 70GB | G12: PL234D607 | H12: 5G 심플 70GB | I12: PL234D607 | J12: 5G Y 베이직 | K12: PL19CB588 | L12: 넷플릭스 초이스 베이직 | M12: PL208A889 | N12: 5G 베이직 복지 | O12: PL2128869 | P12: 현대카드 초이스 프리미엄 | Q12: PL2146252 | R12: 디즈니+ 초이스 스페셜 | S12: PL218N866 | T12: 삼성 초이스 스페셜 | U12: PL21C9617
B13: 5G 심플 50GB | C13: PL234D606 | D13: 5G 심플 50GB | E13: PL234D606 | F13: 5G 심플 50GB | G13: PL234D606 | H13: 5G 심플 50GB | I13: PL234D606 | J13: 넷플릭스 초이스 스페셜 | K13: PL208A884 | L13: 5G 베이직 복지 | M13: PL2128869 | N13: 현대카드 초이스 베이직 | O13: PL2146250 | P13: 디즈니+ 초이스 프리미엄 | Q13: PL218N859 | R13: 삼성 초이스 프리미엄 | S13: PL21C9618 | T13: 우리카드 초이스 프리미엄 | U13: PL21CM713
